Workbook

Sheet 1° Encuesta Filtrada
L1: Eje economico | AD1: Eje social
A2: Marca temporal | B2: Número de Trámite DNI | C2: Año de nacimiento | D2: Año de cursado. La mayoría de las materias obligatorias que cursaste en 2024 son de: | E2: ¿Con qué identidad de género se identifica? | F2: ¿Cuál fue el último nivel educativo alcanzado por su padre o tutor? | G2: ¿Cuál fue el último nivel educativo alcanzado por su madre o tutora? | H2: Ubíquese en la pirámide en base a su ingreso total familiar aproximado | I2: ¿De dónde provienen tus ingresos? | J2: ¿Dónde vivías antes de venir a estudiar a Córdoba? | K2: , | L2: El Estado debe intervenir en el mercado laboral para reducir la brecha salarial entre hombres y mujeres | M2: puntaje | N2: Los países con Estados más “pequeños” (menor gasto público) son más exitosos y sus habitantes gozan de una mejor calidad de vida. | O2: puntaje | P2: Los ricos deben pagar relativamente más impuestos que los pobres | Q2: puntaje | R2: El país sólo puede crecer a largo plazo si reorienta sus políticas hacia una economía de mercado y libre comercio | S2: puntaje | T2: El gobierno siempre debe intervenir en el mercado cuando lo crea necesario | U2: puntaje | V2: Aquellos que puedan trabajar, y rechacen la oportunidad, no deberían esperar ayuda social | W2: puntaje | X2: El gasto público en planes y asistencia social debe reducirse a un mínimo y en su lugar debe gastarse el dinero público en planes de empleo e inversión | Y2: puntaje | Z2: La única responsabilidad social de una empresa debería ser proporcionar utilidades a sus accionistas | AA2: puntaje | AB2: Suma eje economico | AC2: Eje Econ reescalado | AD2: Altos salarios para funcionarios estatales (en los 3 poderes) son beneficiosos por disminuir las posibilidades de que estos cometan actos de corrupción | AE2: puntaje | AF2: Las medidas de restricción de la circulación y aislamiento obligatorio durante la pandemia fueron excesivas y un atropello a la libertad individual de los ciudadanos | AG2: puntaje | AH2: El movimiento feminista carece de sentido ya que actualmente mujeres y hombres se encuentran en pie de igualdad | AI2: puntaje | AJ2: El aborto, cuando no esté amenazada la vida de la madre, siempre debería ser ilegal | AK2: puntaje | AL2: El cambio climático es una problemática alarmante y a la que todos los Estados deberían prestar atención | AM2: puntaje | AN2: Los contribuyentes deberían financiar con impuestos aquellos teatros o museos que no fuesen rentables por sí mismos | AO2: puntaje | AP2: En la justicia penal la rehabilitación debería ser más importante que el castigo | AQ2: puntaje | AR2: Los extranjeros no deberían acceder a educación y salud gratuita | AS2: puntaje | AT2: El Estado no debería obligar a vacunar a los niños | AU2: puntaje | AV2: Eje social | AW2: El peronismo es el responsable de arruinar nuestro país en los últimos años | AX2: La política tradicional es responsable de la crisis económica y social del país | AY2: El FMI es partícipe del fracaso económico de los últimos años | AZ2: La falta de dólares es uno de los principales problemas de la argentina | BA2: Se puede pagar el precio de cierto grado de corrupción, siempre que se solucionen los problemas del país | BB2: Estoy dispuesto a sacrificar derechos políticos por más seguridad | BC2: Estoy dispuesto a sacrificar derechos políticos por más bienestar económico | BD2: Si me asegura 30 años de estabilidad económica y crecimiento, estoy dispuesto a sacrificar derechos políticos | BE2: La vida en los barrios cerrados ("countries") es de mejor calidad que en barrios abiertos, incluso si estos son seguros | BF2: Suponiendo un transporte público eficiente, de calidad y bajo costo, estaría dispuesto a disminuir el uso del automóvil particular | BG2: La educación secundaria privada prepara mejor a los ciudadanos que la escuela pública | BH2: ¿Con cuáles de los siguientes términos se identifica? (Puede elegir más de uno) [De derecha] | BI2: ¿Con cuáles de los siguientes términos se identifica? (Puede elegir más de uno) [De izquierda] | BJ2: ¿Con cuáles de los siguientes términos se identifica? (Puede elegir más de uno) [De centro] | BK2: ¿Con cuáles de los siguientes términos se identifica? (Puede elegir más de uno) [Progresista] | BL2: ¿Con cuáles de los siguientes términos se identifica? (Puede elegir más de uno) [Conservador] | BM2: ¿Con cuáles de los siguientes términos se identifica? (Puede elegir más de uno) [Liberal] | BN2: ¿Con cuáles de los siguientes términos se identifica? (Puede elegir más de uno) [Socialista] | BO2: ¿Con cuáles de los siguientes términos se identifica? (Puede elegir más de uno) [Del PRO] | BP2: ¿Con cuáles de los siguientes términos se identifica? (Puede elegir más de uno) [Peronista] | BQ2: ¿Con cuáles de los siguientes términos se identifica? (Puede elegir más de uno) [Kirchnerista] | BR2: ¿Con cuáles de los siguientes términos se identifica? (Puede elegir más de uno) [Libertario] | BS2: ¿Con cuáles de los siguientes términos se identifica? (Puede elegir más de uno) [Radical] | BT2: ¿Con cuáles de los siguientes términos se identifica? (Puede elegir más de uno) [Macrista] | BU2: ¿Con cuáles de los siguientes términos se identifica? (Puede elegir más de uno) [Feminista] | BV2: ¿Con cuáles de los siguientes términos se identifica? (Puede elegir más de uno) [Ecologista] | BW2: ¿Con cuáles de los siguientes términos se identifica? (Puede elegir más de uno) [Anarquista] | BX2: ¿Cómo votó para Presidente en las elecciones PASO de agosto de 2023? | BY2: ¿Cómo votó para Presidente en las elecciones generales de octubre de 2023? | BZ2: ¿Cómo votó para Presidente en el ballotage de noviembre de 2023? | CA2: ¿Cuál es tu sexo registrado al nacer?
A3: 45553.854 | B3: 00157138797 | C3: 1997 | D3: Quinto año | E3: Varón | F3: Universitario completo | G3: Universitario completo | H3: Clase Media Baja (C3): entre $850.001 mensuales y $1.350.000 mensuales | I3: Trabajo propio | J3: Ciudad de Córdoba | K3: , | L3: Levemente de Acuerdo | M3: =IF(L3="Totalmente de Acuerdo",-1,IF(L3="Muy de Acuerdo",-0.66,IF(L3="Levemente de Acuerdo",-0.33,IF(L3="Levemente en Desacuerdo",0.33,IF(L3="Muy en Desacuerdo",0.66,IF(L3="Totalmente en Desacuerdo",1,"error")))))) -> -0.33 | N3: Levemente en Desacuerdo | O3: =IF(N3="Totalmente de Acuerdo",1,IF(N3="Muy de Acuerdo",0.66,IF(N3="Levemente de Acuerdo",0.33,IF(N3="Levemente en Desacuerdo",-0.33,IF(N3="Muy en Desacuerdo",-0.66,IF(N3="Totalmente en Desacuerdo",-1,"error")))))) -> -0.33 | P3: Muy de Acuerdo | Q3: =IF(P3="Totalmente de Acuerdo",-1,IF(P3="Muy de Acuerdo",-0.66,IF(P3="Levemente de Acuerdo",-0.33,IF(P3="Levemente en Desacuerdo",0.33,IF(P3="Muy en Desacuerdo",0.66,IF(P3="Totalmente en Desacuerdo",1,"error")))))) -> -0.66 | R3: Muy de Acuerdo | S3: =IF(R3="Totalmente de Acuerdo",1,IF(R3="Muy de Acuerdo",0.66,IF(R3="Levemente de Acuerdo",0.33,IF(R3="Levemente en Desacuerdo",-0.33,IF(R3="Muy en Desacuerdo",-0.66,IF(R3="Totalmente en Desacuerdo",-1,"error")))))) -> 0.66 | T3: Levemente de Acuerdo | U3: =IF(T3="Totalmente de Acuerdo",-1,IF(T3="Muy de Acuerdo",-0.66,IF(T3="Levemente de Acuerdo",-0.33,IF(T3="Levemente en Desacuerdo",0.33,IF(T3="Muy en Desacuerdo",0.66,IF(T3="Totalmente en Desacuerdo",1,"error")))))) -> -0.33 | V3: Levemente en Desacuerdo | W3: =IF(V3="Totalmente de Acuerdo",1,IF(V3="Muy de Acuerdo",0.66,IF(V3="Levemente de Acuerdo",0.33,IF(V3="Levemente en Desacuerdo",-0.33,IF(V3="Muy en Desacuerdo",-0.66,IF(V3="Totalmente en Desacuerdo",-1,"error")))))) -> -0.33 | X3: Levemente en Desacuerdo | Y3: =IF(X3="Totalmente de Acuerdo",1,IF(X3="Muy de Acuerdo",0.66,IF(X3="Levemente de Acuerdo",0.33,IF(X3="Levemente en Desacuerdo",-0.33,IF(X3="Muy en Desacuerdo",-0.66,IF(X3="Totalmente en Desacuerdo",-1,"error")))))) -> -0.33 | Z3: Levemente en Desacuerdo | AA3: =IF(Z3="Totalmente de Acuerdo",1,IF(Z3="Muy de Acuerdo",0.66,IF(Z3="Levemente en Acuerdo",0.33,IF(Z3="Levemente en Desacuerdo",-0.33,IF(Z3="Muy en Desacuerdo",-0.66,IF(Z3="Totalmente en Desacuerdo",-1,"error")))))) -> -0.33 | AB3: =+AA3+Y3+W3+U3+S3+Q3+O3+M3 -> -1.98 | AC3: =+AB3*AB$29 -> -2.2275 | AD3: Muy de Acuerdo | AE3: =IF(AD3="Totalmente de Acuerdo",1,IF(AD3="Muy de Acuerdo",0.66,IF(AD3="Levemente de Acuerdo",0.33,IF(AD3="Levemente en Desacuerdo",-0.33,IF(AD3="Muy en Desacuerdo",-0.66,IF(AD3="Totalmente en Desacuerdo",-1,"error")))))) -> 0.66 | AF3: Levemente en Desacuerdo | AG3: =IF(AF3="Totalmente de Acuerdo",-1,IF(AF3="Muy de Acuerdo",-0.66,IF(AF3="Levemente de Acuerdo",-0.33,IF(AF3="Levemente en Desacuerdo",0.33,IF(AF3="Muy en Desacuerdo",0.66,IF(AF3="Totalmente en Desacuerdo",1,"error")))))) -> 0.33 | AH3: Totalmente en Desacuerdo | AI3: =IF(AH3="Totalmente de Acuerdo",1,IF(AH3="Muy de Acuerdo",0.66,IF(AH3="Levemente de Acuerdo",0.33,IF(AH3="Levemente en Desacuerdo",-0.33,IF(AH3="Muy en Desacuerdo",-0.66,IF(AH3="Totalmente en Desacuerdo",-1,"error")))))) -> -1 | AJ3: Totalmente en Desacuerdo | AK3: =IF(AJ3="Totalmente de Acuerdo",1,IF(AJ3="Muy de Acuerdo",0.66,IF(AJ3="Levemente de Acuerdo",0.33,IF(AJ3="Levemente en Desacuerdo",-0.33,IF(AJ3="Muy en Desacuerdo",-0.66,IF(AJ3="Totalmente en Desacuerdo",-1,"error")))))) -> -1 | AL3: Muy en Desacuerdo | AM3: =IF(AL3="Totalmente de Acuerdo",-1,IF(AL3="Muy de Acuerdo",-0.66,IF(AL3="Levemente de Acuerdo",-0.33,IF(AL3="Levemente en Desacuerdo",0.33,IF(AL3="Muy en Desacuerdo",0.66,IF(AL3="Totalmente en Desacuerdo",1,"error")))))) -> 0.66 | AN3: Levemente de Acuerdo | AO3: =IF(AN3="Totalmente de Acuerdo",-1,IF(AN3="Muy de Acuerdo",-0.66,IF(AN3="Levemente de Acuerdo",-0.33,IF(AN3="Levemente en Desacuerdo",0.33,IF(AN3="Muy en Desacuerdo",0.66,IF(AN3="Totalmente en Desacuerdo",1,"error")))))) -> -0.33 | AP3: Levemente en Desacuerdo | AQ3: =IF(AP3="Totalmente de Acuerdo",-1,IF(AP3="Muy de Acuerdo",-0.66,IF(AP3="Levemente de Acuerdo",-0.33,IF(AP3="Levemente en Desacuerdo",0.33,IF(AP3="Muy en Desacuerdo",0.66,IF(AP3="Totalmente en Desacuerdo",1,"error")))))) -> 0.33 | AR3: Levemente en Desacuerdo | AS3: =IF(AR3="Totalmente de Acuerdo",1,IF(AR3="Muy de Acuerdo",0.66,IF(AR3="Levemente de Acuerdo",0.33,IF(AR3="Levemente en Desacuerdo",-0.33,IF(AR3="Muy en Desacuerdo",-0.66,IF(AR3="Totalmente en Desacuerdo",-1,"error")))))) -> -0.33 | AT3: Totalmente en Desacuerdo | AU3: =IF(AT3="Totalmente de Acuerdo",-1,IF(AT3="Muy de Acuerdo",-0.66,IF(AT3="Levemente de Acuerdo",-0.33,IF(AT3="Levemente en Desacuerdo",0.33,IF(AT3="Muy en Desacuerdo",0.66,IF(AT3="Totalmente en Desacuerdo",1,"error")))))) -> 1 | AV3: =+AU3+AS3+AQ3+AO3+AM3+AK3+AI3+AG3+AE3 -> 0.32 | AW3: Totalmente en Desacuerdo | AX3: Levemente de Acuerdo | AY3: Levemente de Acuerdo | AZ3: Levemente de Acuerdo | BA3: Totalmente de Acuerdo | BB3: Totalmente en Desacuerdo | BC3: Muy en Desacuerdo | BD3: Levemente en Desacuerdo | BE3: Totalmente en Desacuerdo | BF3: Levemente de Acuerdo | BG3: Totalmente de Acuerdo | BM3: Me identifico | BP3: Me identifico | BX3: Sergio Massa (Unión por la Patria) | BY3: Sergio Massa (Unión por la Patria) | BZ3: Sergio Massa (Unión por la Patria)
A4: 45547.898 | B4: 00164890275 | C4: 1998 | D4: Quinto año | E4: Varón | F4: Universitario completo | G4: Universitario incompleto | H4: Clase Alta (ABC1): más de $2.850.000 mensuales | I4: Familia | J4: Otra localidad en otra Provincia | K4: , | L4: Levemente de Acuerdo | M4: =IF(L4="Totalmente de Acuerdo",-1,IF(L4="Muy de Acuerdo",-0.66,IF(L4="Levemente de Acuerdo",-0.33,IF(L4="Levemente en Desacuerdo",0.33,IF(L4="Muy en Desacuerdo",0.66,IF(L4="Totalmente en Desacuerdo",1,"error")))))) -> -0.33 | N4: Muy en Desacuerdo | O4: =IF(N4="Totalmente de Acuerdo",1,IF(N4="Muy de Acuerdo",0.66,IF(N4="Levemente de Acuerdo",0.33,IF(N4="Levemente en Desacuerdo",-0.33,IF(N4="Muy en Desacuerdo",-0.66,IF(N4="Totalmente en Desacuerdo",-1,"error")))))) -> -0.66 | P4: Totalmente de Acuerdo | Q4: =IF(P4="Totalmente de Acuerdo",-1,IF(P4="Muy de Acuerdo",-0.66,IF(P4="Levemente de Acuerdo",-0.33,IF(P4="Levemente en Desacuerdo",0.33,IF(P4="Muy en Desacuerdo",0.66,IF(P4="Totalmente en Desacuerdo",1,"error")))))) -> -1 | R4: Levemente de Acuerdo | S4: =IF(R4="Totalmente de Acuerdo",1,IF(R4="Muy de Acuerdo",0.66,IF(R4="Levemente de Acuerdo",0.33,IF(R4="Levemente en Desacuerdo",-0.33,IF(R4="Muy en Desacuerdo",-0.66,IF(R4="Totalmente en Desacuerdo",-1,"error")))))) -> 0.33 | T4: Levemente en Desacuerdo | U4: =IF(T4="Totalmente de Acuerdo",-1,IF(T4="Muy de Acuerdo",-0.66,IF(T4="Levemente de Acuerdo",-0.33,IF(T4="Levemente en Desacuerdo",0.33,IF(T4="Muy en Desacuerdo",0.66,IF(T4="Totalmente en Desacuerdo",1,"error")))))) -> 0.33 | V4: Levemente en Desacuerdo | W4: =IF(V4="Totalmente de Acuerdo",1,IF(V4="Muy de Acuerdo",0.66,IF(V4="Levemente de Acuerdo",0.33,IF(V4="Levemente en Desacuerdo",-0.33,IF(V4="Muy en Desacuerdo",-0.66,IF(V4="Totalmente en Desacuerdo",-1,"error")))))) -> -0.33 | X4: Levemente en Desacuerdo | Y4: =IF(X4="Totalmente de Acuerdo",1,IF(X4="Muy de Acuerdo",0.66,IF(X4="Levemente de Acuerdo",0.33,IF(X4="Levemente en Desacuerdo",-0.33,IF(X4="Muy en Desacuerdo",-0.66,IF(X4="Totalmente en Desacuerdo",-1,"error")))))) -> -0.33 | Z4: Muy en Desacuerdo | AA4: =IF(Z4="Totalmente de Acuerdo",1,IF(Z4="Muy de Acuerdo",0.66,IF(Z4="Levemente en Acuerdo",0.33,IF(Z4="Levemente en Desacuerdo",-0.33,IF(Z4="Muy en Desacuerdo",-0.66,IF(Z4="Totalmente en Desacuerdo",-1,"error")))))) -> -0.66 | AB4: =+AA4+Y4+W4+U4+S4+Q4+O4+M4 -> -2.65 | AC4: =+AB4*AB$29 -> -2.98125 | AD4: Levemente de Acuerdo | AE4: =IF(AD4="Totalmente de Acuerdo",1,IF(AD4="Muy de Acuerdo",0.66,IF(AD4="Levemente de Acuerdo",0.33,IF(AD4="Levemente en Desacuerdo",-0.33,IF(AD4="Muy en Desacuerdo",-0.66,IF(AD4="Totalmente en Desacuerdo",-1,"error")))))) -> 0.33 | AF4: Levemente de Acuerdo | AG4: =IF(AF4="Totalmente de Acuerdo",-1,IF(AF4="Muy de Acuerdo",-0.66,IF(AF4="Levemente de Acuerdo",-0.33,IF(AF4="Levemente en Desacuerdo",0.33,IF(AF4="Muy en Desacuerdo",0.66,IF(AF4="Totalmente en Desacuerdo",1,"error")))))) -> -0.33 | AH4: Totalmente en Desacuerdo | AI4: =IF(AH4="Totalmente de Acuerdo",1,IF(AH4="Muy de Acuerdo",0.66,IF(AH4="Levemente de Acuerdo",0.33,IF(AH4="Levemente en Desacuerdo",-0.33,IF(AH4="Muy en Desacuerdo",-0.66,IF(AH4="Totalmente en Desacuerdo",-1,"error")))))) -> -1 | AJ4: Totalmente en Desacuerdo | AK4: =IF(AJ4="Totalmente de Acuerdo",1,IF(AJ4="Muy de Acuerdo",0.66,IF(AJ4="Levemente de Acuerdo",0.33,IF(AJ4="Levemente en Desacuerdo",-0.33,IF(AJ4="Muy en Desacuerdo",-0.66,IF(AJ4="Totalmente en Desacuerdo",-1,"error")))))) -> -1 | AL4: Muy de Acuerdo | AM4: =IF(AL4="Totalmente de Acuerdo",-1,IF(AL4="Muy de Acuerdo",-0.66,IF(AL4="Levemente de Acuerdo",-0.33,IF(AL4="Levemente en Desacuerdo",0.33,IF(AL4="Muy en Desacuerdo",0.66,IF(AL4="Totalmente en Desacuerdo",1,"error")))))) -> -0.66 | AN4: Muy de Acuerdo | AO4: =IF(AN4="Totalmente de Acuerdo",-1,IF(AN4="Muy de Acuerdo",-0.66,IF(AN4="Levemente de Acuerdo",-0.33,IF(AN4="Levemente en Desacuerdo",0.33,IF(AN4="Muy en Desacuerdo",0.66,IF(AN4="Totalmente en Desacuerdo",1,"error")))))) -> -0.66 | AP4: Muy de Acuerdo | AQ4: =IF(AP4="Totalmente de Acuerdo",-1,IF(AP4="Muy de Acuerdo",-0.66,IF(AP4="Levemente de Acuerdo",-0.33,IF(AP4="Levemente en Desacuerdo",0.33,IF(AP4="Muy en Desacuerdo",0.66,IF(AP4="Totalmente en Desacuerdo",1,"error")))))) -> -0.66 | AR4: Totalmente en Desacuerdo | AS4: =IF(AR4="Totalmente de Acuerdo",1,IF(AR4="Muy de Acuerdo",0.66,IF(AR4="Levemente de Acuerdo",0.33,IF(AR4="Levemente en Desacuerdo",-0.33,IF(AR4="Muy en Desacuerdo",-0.66,IF(AR4="Totalmente en Desacuerdo",-1,"error")))))) -> -1 | AT4: Totalmente en Desacuerdo | AU4: =IF(AT4="Totalmente de Acuerdo",-1,IF(AT4="Muy de Acuerdo",-0.66,IF(AT4="Levemente de Acuerdo",-0.33,IF(AT4="Levemente en Desacuerdo",0.33,IF(AT4="Muy en Desacuerdo",0.66,IF(AT4="Totalmente en Desacuerdo",1,"error")))))) -> 1 | AV4: =+AU4+AS4+AQ4+AO4+AM4+AK4+AI4+AG4+AE4 -> -3.98 | AW4: Totalmente en Desacuerdo | AX4: Levemente de Acuerdo | AY4: Levemente de Acuerdo | AZ4: Levemente de Acuerdo | BA4: Levemente en Desacuerdo | BB4: Muy en Desacuerdo | BC4: Muy en Desacuerdo | BD4: Levemente en Desacuerdo | BE4: Levemente en Desacuerdo | BF4: Muy de Acuerdo | BG4: Levemente de Acuerdo | BJ4: Me identifico | BK4: Me identifico | BX4: Horacio Rodríguez Larreta (Juntos por el Cambio) | BY4: Sergio Massa (Unión por la Patria) | BZ4: Sergio Massa (Unión por la Patria)
A5: 45560.553 | B5: 00284397411 | C5: 1999 | D5: Cuarto año | E5: Otra | F5: Universitario completo | G5: Posgrado completo | H5: Clase Media Alta (C2): entre $1.350.001 mensuales y $2.850.000 mensuales | I5: Trabajo propio | J5: Otra localidad en otra Provincia | K5: , | L5: Muy de Acuerdo | M5: =IF(L5="Totalmente de Acuerdo",-1,IF(L5="Muy de Acuerdo",-0.66,IF(L5="Levemente de Acuerdo",-0.33,IF(L5="Levemente en Desacuerdo",0.33,IF(L5="Muy en Desacuerdo",0.66,IF(L5="Totalmente en Desacuerdo",1,"error")))))) -> -0.66 | N5: Muy en Desacuerdo | O5: =IF(N5="Totalmente de Acuerdo",1,IF(N5="Muy de Acuerdo",0.66,IF(N5="Levemente de Acuerdo",0.33,IF(N5="Levemente en Desacuerdo",-0.33,IF(N5="Muy en Desacuerdo",-0.66,IF(N5="Totalmente en Desacuerdo",-1,"error")))))) -> -0.66 | P5: Totalmente de Acuerdo | Q5: =IF(P5="Totalmente de Acuerdo",-1,IF(P5="Muy de Acuerdo",-0.66,IF(P5="Levemente de Acuerdo",-0.33,IF(P5="Levemente en Desacuerdo",0.33,IF(P5="Muy en Desacuerdo",0.66,IF(P5="Totalmente en Desacuerdo",1,"error")))))) -> -1 | R5: Totalmente en Desacuerdo | S5: =IF(R5="Totalmente de Acuerdo",1,IF(R5="Muy de Acuerdo",0.66,IF(R5="Levemente de Acuerdo",0.33,IF(R5="Levemente en Desacuerdo",-0.33,IF(R5="Muy en Desacuerdo",-0.66,IF(R5="Totalmente en Desacuerdo",-1,"error")))))) -> -1 | T5: Muy de Acuerdo | U5: =IF(T5="Totalmente de Acuerdo",-1,IF(T5="Muy de Acuerdo",-0.66,IF(T5="Levemente de Acuerdo",-0.33,IF(T5="Levemente en Desacuerdo",0.33,IF(T5="Muy en Desacuerdo",0.66,IF(T5="Totalmente en Desacuerdo",1,"error")))))) -> -0.66 | V5: Levemente de Acuerdo | W5: =IF(V5="Totalmente de Acuerdo",1,IF(V5="Muy de Acuerdo",0.66,IF(V5="Levemente de Acuerdo",0.33,IF(V5="Levemente en Desacuerdo",-0.33,IF(V5="Muy en Desacuerdo",-0.66,IF(V5="Totalmente en Desacuerdo",-1,"error")))))) -> 0.33 | X5: Levemente en Desacuerdo | Y5: =IF(X5="Totalmente de Acuerdo",1,IF(X5="Muy de Acuerdo",0.66,IF(X5="Levemente de Acuerdo",0.33,IF(X5="Levemente en Desacuerdo",-0.33,IF(X5="Muy en Desacuerdo",-0.66,IF(X5="Totalmente en Desacuerdo",-1,"error")))))) -> -0.33 | Z5: Totalmente en Desacuerdo | AA5: =IF(Z5="Totalmente de Acuerdo",1,IF(Z5="Muy de Acuerdo",0.66,IF(Z5="Levemente en Acuerdo",0.33,IF(Z5="Levemente en Desacuerdo",-0.33,IF(Z5="Muy en Desacuerdo",-0.66,IF(Z5="Totalmente en Desacuerdo",-1,"error")))))) -> -1 | AB5: =+AA5+Y5+W5+U5+S5+Q5+O5+M5 -> -4.98 | AC5: =+AB5*AB$29 -> -5.6025 | AD5: Muy en Desacuerdo | AE5: =IF(AD5="Totalmente de Acuerdo",1,IF(AD5="Muy de Acuerdo",0.66,IF(AD5="Levemente de Acuerdo",0.33,IF(AD5="Levemente en Desacuerdo",-0.33,IF(AD5="Muy en Desacuerdo",-0.66,IF(AD5="Totalmente en Desacuerdo",-1,"error")))))) -> -0.66 | AF5: Muy en Desacuerdo | AG5: =IF(AF5="Totalmente de Acuerdo",-1,IF(AF5="Muy de Acuerdo",-0.66,IF(AF5="Levemente de Acuerdo",-0.33,IF(AF5="Levemente en Desacuerdo",0.33,IF(AF5="Muy en Desacuerdo",0.66,IF(AF5="Totalmente en Desacuerdo",1,"error")))))) -> 0.66 | AH5: Totalmente en Desacuerdo | AI5: =IF(AH5="Totalmente de Acuerdo",1,IF(AH5="Muy de Acuerdo",0.66,IF(AH5="Levemente de Acuerdo",0.33,IF(AH5="Levemente en Desacuerdo",-0.33,IF(AH5="Muy en Desacuerdo",-0.66,IF(AH5="Totalmente en Desacuerdo",-1,"error")))))) -> -1 | AJ5: Totalmente en Desacuerdo | AK5: =IF(AJ5="Totalmente de Acuerdo",1,IF(AJ5="Muy de Acuerdo",0.66,IF(AJ5="Levemente de Acuerdo",0.33,IF(AJ5="Levemente en Desacuerdo",-0.33,IF(AJ5="Muy en Desacuerdo",-0.66,IF(AJ5="Totalmente en Desacuerdo",-1,"error")))))) -> -1 | AL5: Totalmente de Acuerdo | AM5: =IF(AL5="Totalmente de Acuerdo",-1,IF(AL5="Muy de Acuerdo",-0.66,IF(AL5="Levemente de Acuerdo",-0.33,IF(AL5="Levemente en Desacuerdo",0.33,IF(AL5="Muy en Desacuerdo",0.66,IF(AL5="Totalmente en Desacuerdo",1,"error")))))) -> -1 | AN5: Levemente de Acuerdo | AO5: =IF(AN5="Totalmente de Acuerdo",-1,IF(AN5="Muy de Acuerdo",-0.66,IF(AN5="Levemente de Acuerdo",-0.33,IF(AN5="Levemente en Desacuerdo",0.33,IF(AN5="Muy en Desacuerdo",0.66,IF(AN5="Totalmente en Desacuerdo",1,"error")))))) -> -0.33 | AP5: Muy de Acuerdo | AQ5: =IF(AP5="Totalmente de Acuerdo",-1,IF(AP5="Muy de Acuerdo",-0.66,IF(AP5="Levemente de Acuerdo",-0.33,IF(AP5="Levemente en Desacuerdo",0.33,IF(AP5="Muy en Desacuerdo",0.66,IF(AP5="Totalmente en Desacuerdo",1,"error")))))) -> -0.66 | AR5: Totalmente en Desacuerdo | AS5: =IF(AR5="Totalmente de Acuerdo",1,IF(AR5="Muy de Acuerdo",0.66,IF(AR5="Levemente de Acuerdo",0.33,IF(AR5="Levemente en Desacuerdo",-0.33,IF(AR5="Muy en Desacuerdo",-0.66,IF(AR5="Totalmente en Desacuerdo",-1,"error")))))) -> -1 | AT5: Levemente en Desacuerdo | AU5: =IF(AT5="Totalmente de Acuerdo",-1,IF(AT5="Muy de Acuerdo",-0.66,IF(AT5="Levemente de Acuerdo",-0.33,IF(AT5="Levemente en Desacuerdo",0.33,IF(AT5="Muy en Desacuerdo",0.66,IF(AT5="Totalmente en Desacuerdo",1,"error")))))) -> 0.33 | AV5: =+AU5+AS5+AQ5+AO5+AM5+AK5+AI5+AG5+AE5 -> -4.66 | AW5: Totalmente en Desacuerdo | AX5: Levemente en Desacuerdo | AY5: Muy de Acuerdo | AZ5: Levemente de Acuerdo | BA5: Muy en Desacuerdo | BB5: Totalmente en Desacuerdo | BC5: Totalmente en Desacuerdo | BD5: Totalmente en Desacuerdo | BE5: Totalmente en Desacuerdo | BF5: Muy de Acuerdo | BG5: Totalmente en Desacuerdo | BP5: Me identifico | BQ5: Me identifico | BU5: Me identifico | BX5: Sergio Massa (Unión por la Patria) | BY5: Sergio Massa (Unión por la Patria) | BZ5: Sergio Massa (Unión por la Patria)
A6: 45547.9 | B6: 00305830361 | C6: 2000 | D6: Cuarto año | E6: Mujer | F6: Universitario completo | G6: Posgrado completo | H6: Clase Media Alta (C2): entre $1.350.001 mensuales y $2.850.000 mensuales | I6: Trabajo propio | J6: Ciudad de Córdoba | K6: , | L6: Muy de Acuerdo | M6: =IF(L6="Totalmente de Acuerdo",-1,IF(L6="Muy de Acuerdo",-0.66,IF(L6="Levemente de Acuerdo",-0.33,IF(L6="Levemente en Desacuerdo",0.33,IF(L6="Muy en Desacuerdo",0.66,IF(L6="Totalmente en Desacuerdo",1,"error")))))) -> -0.66 | N6: Levemente en Desacuerdo | O6: =IF(N6="Totalmente de Acuerdo",1,IF(N6="Muy de Acuerdo",0.66,IF(N6="Levemente de Acuerdo",0.33,IF(N6="Levemente en Desacuerdo",-0.33,IF(N6="Muy en Desacuerdo",-0.66,IF(N6="Totalmente en Desacuerdo",-1,"error")))))) -> -0.33 | P6: Muy de Acuerdo | Q6: =IF(P6="Totalmente de Acuerdo",-1,IF(P6="Muy de Acuerdo",-0.66,IF(P6="Levemente de Acuerdo",-0.33,IF(P6="Levemente en Desacuerdo",0.33,IF(P6="Muy en Desacuerdo",0.66,IF(P6="Totalmente en Desacuerdo",1,"error")))))) -> -0.66 | R6: Muy de Acuerdo | S6: =IF(R6="Totalmente de Acuerdo",1,IF(R6="Muy de Acuerdo",0.66,IF(R6="Levemente de Acuerdo",0.33,IF(R6="Levemente en Desacuerdo",-0.33,IF(R6="Muy en Desacuerdo",-0.66,IF(R6="Totalmente en Desacuerdo",-1,"error")))))) -> 0.66 | T6: Muy en Desacuerdo | U6: =IF(T6="Totalmente de Acuerdo",-1,IF(T6="Muy de Acuerdo",-0.66,IF(T6="Levemente de Acuerdo",-0.33,IF(T6="Levemente en Desacuerdo",0.33,IF(T6="Muy en Desacuerdo",0.66,IF(T6="Totalmente en Desacuerdo",1,"error")))))) -> 0.66 | V6: Muy de Acuerdo | W6: =IF(V6="Totalmente de Acuerdo",1,IF(V6="Muy de Acuerdo",0.66,IF(V6="Levemente de Acuerdo",0.33,IF(V6="Levemente en Desacuerdo",-0.33,IF(V6="Muy en Desacuerdo",-0.66,IF(V6="Totalmente en Desacuerdo",-1,"error")))))) -> 0.66 | X6: Levemente en Desacuerdo | Y6: =IF(X6="Totalmente de Acuerdo",1,IF(X6="Muy de Acuerdo",0.66,IF(X6="Levemente de Acuerdo",0.33,IF(X6="Levemente en Desacuerdo",-0.33,IF(X6="Muy en Desacuerdo",-0.66,IF(X6="Totalmente en Desacuerdo",-1,"error")))))) -> -0.33 | Z6: Muy en Desacuerdo | AA6: =IF(Z6="Totalmente de Acuerdo",1,IF(Z6="Muy de Acuerdo",0.66,IF(Z6="Levemente en Acuerdo",0.33,IF(Z6="Levemente en Desacuerdo",-0.33,IF(Z6="Muy en Desacuerdo",-0.66,IF(Z6="Totalmente en Desacuerdo",-1,"error")))))) -> -0.66 | AB6: =+AA6+Y6+W6+U6+S6+Q6+O6+M6 -> -0.66 | AC6: =+AB6*AB$29 -> -0.7425 | AD6: Muy en Desacuerdo | AE6: =IF(AD6="Totalmente de Acuerdo",1,IF(AD6="Muy de Acuerdo",0.66,IF(AD6="Levemente de Acuerdo",0.33,IF(AD6="Levemente en Desacuerdo",-0.33,IF(AD6="Muy en Desacuerdo",-0.66,IF(AD6="Totalmente en Desacuerdo",-1,"error")))))) -> -0.66 | AF6: Muy de Acuerdo | AG6: =IF(AF6="Totalmente de Acuerdo",-1,IF(AF6="Muy de Acuerdo",-0.66,IF(AF6="Levemente de Acuerdo",-0.33,IF(AF6="Levemente en Desacuerdo",0.33,IF(AF6="Muy en Desacuerdo",0.66,IF(AF6="Totalmente en Desacuerdo",1,"error")))))) -> -0.66 | AH6: Levemente en Desacuerdo | AI6: =IF(AH6="Totalmente de Acuerdo",1,IF(AH6="Muy de Acuerdo",0.66,IF(AH6="Levemente de Acuerdo",0.33,IF(AH6="Levemente en Desacuerdo",-0.33,IF(AH6="Muy en Desacuerdo",-0.66,IF(AH6="Totalmente en Desacuerdo",-1,"error")))))) -> -0.33 | AJ6: Levemente de Acuerdo | AK6: =IF(AJ6="Totalmente de Acuerdo",1,IF(AJ6="Muy de Acuerdo",0.66,IF(AJ6="Levemente de Acuerdo",0.33,IF(AJ6="Levemente en Desacuerdo",-0.33,IF(AJ6="Muy en Desacuerdo",-0.66,IF(AJ6="Totalmente en Desacuerdo",-1,"error")))))) -> 0.33 | AL6: Totalmente de Acuerdo | AM6: =IF(AL6="Totalmente de Acuerdo",-1,IF(AL6="Muy de Acuerdo",-0.66,IF(AL6="Levemente de Acuerdo",-0.33,IF(AL6="Levemente en Desacuerdo",0.33,IF(AL6="Muy en Desacuerdo",0.66,IF(AL6="Totalmente en Desacuerdo",1,"error")))))) -> -1 | AN6: Levemente de Acuerdo | AO6: =IF(AN6="Totalmente de Acuerdo",-1,IF(AN6="Muy de Acuerdo",-0.66,IF(AN6="Levemente de Acuerdo",-0.33,IF(AN6="Levemente en Desacuerdo",0.33,IF(AN6="Muy en Desacuerdo",0.66,IF(AN6="Totalmente en Desacuerdo",1,"error")))))) -> -0.33 | AP6: Muy de Acuerdo | AQ6: =IF(AP6="Totalmente de Acuerdo",-1,IF(AP6="Muy de Acuerdo",-0.66,IF(AP6="Levemente de Acuerdo",-0.33,IF(AP6="Levemente en Desacuerdo",0.33,IF(AP6="Muy en Desacuerdo",0.66,IF(AP6="Totalmente en Desacuerdo",1,"error")))))) -> -0.66 | AR6: Totalmente de Acuerdo | AS6: =IF(AR6="Totalmente de Acuerdo",1,IF(AR6="Muy de Acuerdo",0.66,IF(AR6="Levemente de Acuerdo",0.33,IF(AR6="Levemente en Desacuerdo",-0.33,IF(AR6="Muy en Desacuerdo",-0.66,IF(AR6="Totalmente en Desacuerdo",-1,"error")))))) -> 1 | AT6: Muy en Desacuerdo | AU6: =IF(AT6="Totalmente de Acuerdo",-1,IF(AT6="Muy de Acuerdo",-0.66,IF(AT6="Levemente de Acuerdo",-0.33,IF(AT6="Levemente en Desacuerdo",0.33,IF(AT6="Muy en Desacuerdo",0.66,IF(AT6="Totalmente en Desacuerdo",1,"error")))))) -> 0.66 | AV6: =+AU6+AS6+AQ6+AO6+AM6+AK6+AI6+AG6+AE6 -> -1.65 | AW6: Levemente de Acuerdo | AX6: Levemente en Desacuerdo | AY6: Levemente en Desacuerdo | AZ6: Muy de Acuerdo | BA6: Muy de Acuerdo | BB6: Levemente de Acuerdo | BC6: Levemente de Acuerdo | BD6: Muy de Acuerdo | BE6: Muy en Desacuerdo | BF6: Totalmente de Acuerdo | BG6: Muy de Acuerdo | BJ6: Me identifico | BV6: Me identifico | BX6: Juan Schiaretti (Hacemos por Nuestro País) | BY6: Juan Schiaretti (Hacemos por Nuestro País) | BZ6: En blanco
A7: 45547.9 | B7: 00338374873 | C7: 2000 | D7: Quinto año | E7: Mujer | F7: Posgrado completo | G7: Posgrado completo | H7: Clase Alta (ABC1): más de $2.850.000 mensuales | I7: Familia | J7: Otra localidad en la Provincia de Córdoba | K7: , | L7: Levemente de Acuerdo | M7: =IF(L7="Totalmente de Acuerdo",-1,IF(L7="Muy de Acuerdo",-0.66,IF(L7="Levemente de Acuerdo",-0.33,IF(L7="Levemente en Desacuerdo",0.33,IF(L7="Muy en Desacuerdo",0.66,IF(L7="Totalmente en Desacuerdo",1,"error")))))) -> -0.33 | N7: Levemente en Desacuerdo | O7: =IF(N7="Totalmente de Acuerdo",1,IF(N7="Muy de Acuerdo",0.66,IF(N7="Levemente de Acuerdo",0.33,IF(N7="Levemente en Desacuerdo",-0.33,IF(N7="Muy en Desacuerdo",-0.66,IF(N7="Totalmente en Desacuerdo",-1,"error")))))) -> -0.33 | P7: Muy de Acuerdo | Q7: =IF(P7="Totalmente de Acuerdo",-1,IF(P7="Muy de Acuerdo",-0.66,IF(P7="Levemente de Acuerdo",-0.33,IF(P7="Levemente en Desacuerdo",0.33,IF(P7="Muy en Desacuerdo",0.66,IF(P7="Totalmente en Desacuerdo",1,"error")))))) -> -0.66 | R7: Levemente de Acuerdo | S7: =IF(R7="Totalmente de Acuerdo",1,IF(R7="Muy de Acuerdo",0.66,IF(R7="Levemente de Acuerdo",0.33,IF(R7="Levemente en Desacuerdo",-0.33,IF(R7="Muy en Desacuerdo",-0.66,IF(R7="Totalmente en Desacuerdo",-1,"error")))))) -> 0.33 | T7: Levemente de Acuerdo | U7: =IF(T7="Totalmente de Acuerdo",-1,IF(T7="Muy de Acuerdo",-0.66,IF(T7="Levemente de Acuerdo",-0.33,IF(T7="Levemente en Desacuerdo",0.33,IF(T7="Muy en Desacuerdo",0.66,IF(T7="Totalmente en Desacuerdo",1,"error")))))) -> -0.33 | V7: Muy de Acuerdo | W7: =IF(V7="Totalmente de Acuerdo",1,IF(V7="Muy de Acuerdo",0.66,IF(V7="Levemente de Acuerdo",0.33,IF(V7="Levemente en Desacuerdo",-0.33,IF(V7="Muy en Desacuerdo",-0.66,IF(V7="Totalmente en Desacuerdo",-1,"error")))))) -> 0.66 | X7: Levemente en Desacuerdo | Y7: =IF(X7="Totalmente de Acuerdo",1,IF(X7="Muy de Acuerdo",0.66,IF(X7="Levemente de Acuerdo",0.33,IF(X7="Levemente en Desacuerdo",-0.33,IF(X7="Muy en Desacuerdo",-0.66,IF(X7="Totalmente en Desacuerdo",-1,"error")))))) -> -0.33 | Z7: Levemente en Desacuerdo | AA7: =IF(Z7="Totalmente de Acuerdo",1,IF(Z7="Muy de Acuerdo",0.66,IF(Z7="Levemente en Acuerdo",0.33,IF(Z7="Levemente en Desacuerdo",-0.33,IF(Z7="Muy en Desacuerdo",-0.66,IF(Z7="Totalmente en Desacuerdo",-1,"error")))))) -> -0.33 | AB7: =+AA7+Y7+W7+U7+S7+Q7+O7+M7 -> -1.32 | AC7: =+AB7*AB$29 -> -1.485 | AD7: Levemente de Acuerdo | AE7: =IF(AD7="Totalmente de Acuerdo",1,IF(AD7="Muy de Acuerdo",0.66,IF(AD7="Levemente de Acuerdo",0.33,IF(AD7="Levemente en Desacuerdo",-0.33,IF(AD7="Muy en Desacuerdo",-0.66,IF(AD7="Totalmente en Desacuerdo",-1,"error")))))) -> 0.33 | AF7: Muy de Acuerdo | AG7: =IF(AF7="Totalmente de Acuerdo",-1,IF(AF7="Muy de Acuerdo",-0.66,IF(AF7="Levemente de Acuerdo",-0.33,IF(AF7="Levemente en Desacuerdo",0.33,IF(AF7="Muy en Desacuerdo",0.66,IF(AF7="Totalmente en Desacuerdo",1,"error")))))) -> -0.66 | AH7: Totalmente en Desacuerdo | AI7: =IF(AH7="Totalmente de Acuerdo",1,IF(AH7="Muy de Acuerdo",0.66,IF(AH7="Levemente de Acuerdo",0.33,IF(AH7="Levemente en Desacuerdo",-0.33,IF(AH7="Muy en Desacuerdo",-0.66,IF(AH7="Totalmente en Desacuerdo",-1,"error")))))) -> -1 | AJ7: Totalmente en Desacuerdo | AK7: =IF(AJ7="Totalmente de Acuerdo",1,IF(AJ7="Muy de Acuerdo",0.66,IF(AJ7="Levemente de Acuerdo",0.33,IF(AJ7="Levemente en Desacuerdo",-0.33,IF(AJ7="Muy en Desacuerdo",-0.66,IF(AJ7="Totalmente en Desacuerdo",-1,"error")))))) -> -1 | AL7: Levemente de Acuerdo | AM7: =IF(AL7="Totalmente de Acuerdo",-1,IF(AL7="Muy de Acuerdo",-0.66,IF(AL7="Levemente de Acuerdo",-0.33,IF(AL7="Levemente en Desacuerdo",0.33,IF(AL7="Muy en Desacuerdo",0.66,IF(AL7="Totalmente en Desacuerdo",1,"error")))))) -> -0.33 | AN7: Levemente en Desacuerdo | AO7: =IF(AN7="Totalmente de Acuerdo",-1,IF(AN7="Muy de Acuerdo",-0.66,IF(AN7="Levemente de Acuerdo",-0.33,IF(AN7="Levemente en Desacuerdo",0.33,IF(AN7="Muy en Desacuerdo",0.66,IF(AN7="Totalmente en Desacuerdo",1,"error")))))) -> 0.33 | AP7: Levemente de Acuerdo | AQ7: =IF(AP7="Totalmente de Acuerdo",-1,IF(AP7="Muy de Acuerdo",-0.66,IF(AP7="Levemente de Acuerdo",-0.33,IF(AP7="Levemente en Desacuerdo",0.33,IF(AP7="Muy en Desacuerdo",0.66,IF(AP7="Totalmente en Desacuerdo",1,"error")))))) -> -0.33 | AR7: Muy de Acuerdo | AS7: =IF(AR7="Totalmente de Acuerdo",1,IF(AR7="Muy de Acuerdo",0.66,IF(AR7="Levemente de Acuerdo",0.33,IF(AR7="Levemente en Desacuerdo",-0.33,IF(AR7="Muy en Desacuerdo",-0.66,IF(AR7="Totalmente en Desacuerdo",-1,"error")))))) -> 0.66 | AT7: Muy en Desacuerdo | AU7: =IF(AT7="Totalmente de Acuerdo",-1,IF(AT7="Muy de Acuerdo",-0.66,IF(AT7="Levemente de Acuerdo",-0.33,IF(AT7="Levemente en Desacuerdo",0.33,IF(AT7="Muy en Desacuerdo",0.66,IF(AT7="Totalmente en Desacuerdo",1,"error")))))) -> 0.66 | AV7: =+AU7+AS7+AQ7+AO7+AM7+AK7+AI7+AG7+AE7 -> -1.34 | AW7: Levemente de Acuerdo | AX7: Levemente de Acuerdo | AY7: Muy en Desacuerdo | AZ7: Levemente en Desacuerdo | BA7: Muy de Acuerdo | BB7: Levemente en Desacuerdo | BC7: Levemente en Desacuerdo | BD7: Levemente de Acuerdo | BE7: Muy en Desacuerdo | BF7: Muy de Acuerdo | BG7: Muy de Acuerdo | BJ7: Me identifico | BK7: Me identifico | BU7: Me identifico | BX7: No vote | BY7: Javier Milei (La Libertad Avanza) | BZ7: Javier Milei (La Libertad Avanza)
A8: 45553.88 | B8: 003420609968086 | C8: 2000 | D8: Quinto año | E8: Varón | F8: Secundario completo | G8: Terciario completo | H8: Clase Media Baja (C3): entre $850.001 mensuales y $1.350.000 mensuales | I8: Beca|Pasantia|Familia | J8: Otra localidad en la Provincia de Córdoba | K8: , | L8: Muy de Acuerdo | M8: =IF(L8="Totalmente de Acuerdo",-1,IF(L8="Muy de Acuerdo",-0.66,IF(L8="Levemente de Acuerdo",-0.33,IF(L8="Levemente en Desacuerdo",0.33,IF(L8="Muy en Desacuerdo",0.66,IF(L8="Totalmente en Desacuerdo",1,"error")))))) -> -0.66 | N8: Levemente en Desacuerdo | O8: =IF(N8="Totalmente de Acuerdo",1,IF(N8="Muy de Acuerdo",0.66,IF(N8="Levemente de Acuerdo",0.33,IF(N8="Levemente en Desacuerdo",-0.33,IF(N8="Muy en Desacuerdo",-0.66,IF(N8="Totalmente en Desacuerdo",-1,"error")))))) -> -0.33 | P8: Muy de Acuerdo | Q8: =IF(P8="Totalmente de Acuerdo",-1,IF(P8="Muy de Acuerdo",-0.66,IF(P8="Levemente de Acuerdo",-0.33,IF(P8="Levemente en Desacuerdo",0.33,IF(P8="Muy en Desacuerdo",0.66,IF(P8="Totalmente en Desacuerdo",1,"error")))))) -> -0.66 | R8: Levemente de Acuerdo | S8: =IF(R8="Totalmente de Acuerdo",1,IF(R8="Muy de Acuerdo",0.66,IF(R8="Levemente de Acuerdo",0.33,IF(R8="Levemente en Desacuerdo",-0.33,IF(R8="Muy en Desacuerdo",-0.66,IF(R8="Totalmente en Desacuerdo",-1,"error")))))) -> 0.33 | T8: Muy de Acuerdo | U8: =IF(T8="Totalmente de Acuerdo",-1,IF(T8="Muy de Acuerdo",-0.66,IF(T8="Levemente de Acuerdo",-0.33,IF(T8="Levemente en Desacuerdo",0.33,IF(T8="Muy en Desacuerdo",0.66,IF(T8="Totalmente en Desacuerdo",1,"error")))))) -> -0.66 | V8: Muy de Acuerdo | W8: =IF(V8="Totalmente de Acuerdo",1,IF(V8="Muy de Acuerdo",0.66,IF(V8="Levemente de Acuerdo",0.33,IF(V8="Levemente en Desacuerdo",-0.33,IF(V8="Muy en Desacuerdo",-0.66,IF(V8="Totalmente en Desacuerdo",-1,"error")))))) -> 0.66 | X8: Levemente en Desacuerdo | Y8: =IF(X8="Totalmente de Acuerdo",1,IF(X8="Muy de Acuerdo",0.66,IF(X8="Levemente de Acuerdo",0.33,IF(X8="Levemente en Desacuerdo",-0.33,IF(X8="Muy en Desacuerdo",-0.66,IF(X8="Totalmente en Desacuerdo",-1,"error")))))) -> -0.33 | Z8: Muy en Desacuerdo | AA8: =IF(Z8="Totalmente de Acuerdo",1,IF(Z8="Muy de Acuerdo",0.66,IF(Z8="Levemente en Acuerdo",0.33,IF(Z8="Levemente en Desacuerdo",-0.33,IF(Z8="Muy en Desacuerdo",-0.66,IF(Z8="Totalmente en Desacuerdo",-1,"error")))))) -> -0.66 | AB8: =+AA8+Y8+W8+U8+S8+Q8+O8+M8 -> -2.31 | AC8: =+AB8*AB$29 -> -2.59875 | AD8: Levemente en Desacuerdo | AE8: =IF(AD8="Totalmente de Acuerdo",1,IF(AD8="Muy de Acuerdo",0.66,IF(AD8="Levemente de Acuerdo",0.33,IF(AD8="Levemente en Desacuerdo",-0.33,IF(AD8="Muy en Desacuerdo",-0.66,IF(AD8="Totalmente en Desacuerdo",-1,"error")))))) -> -0.33 | AF8: Muy de Acuerdo | AG8: =IF(AF8="Totalmente de Acuerdo",-1,IF(AF8="Muy de Acuerdo",-0.66,IF(AF8="Levemente de Acuerdo",-0.33,IF(AF8="Levemente en Desacuerdo",0.33,IF(AF8="Muy en Desacuerdo",0.66,IF(AF8="Totalmente en Desacuerdo",1,"error")))))) -> -0.66 | AH8: Muy en Desacuerdo | AI8: =IF(AH8="Totalmente de Acuerdo",1,IF(AH8="Muy de Acuerdo",0.66,IF(AH8="Levemente de Acuerdo",0.33,IF(AH8="Levemente en Desacuerdo",-0.33,IF(AH8="Muy en Desacuerdo",-0.66,IF(AH8="Totalmente en Desacuerdo",-1,"error")))))) -> -0.66 | AJ8: Muy en Desacuerdo | AK8: =IF(AJ8="Totalmente de Acuerdo",1,IF(AJ8="Muy de Acuerdo",0.66,IF(AJ8="Levemente de Acuerdo",0.33,IF(AJ8="Levemente en Desacuerdo",-0.33,IF(AJ8="Muy en Desacuerdo",-0.66,IF(AJ8="Totalmente en Desacuerdo",-1,"error")))))) -> -0.66 | AL8: Totalmente de Acuerdo | AM8: =IF(AL8="Totalmente de Acuerdo",-1,IF(AL8="Muy de Acuerdo",-0.66,IF(AL8="Levemente de Acuerdo",-0.33,IF(AL8="Levemente en Desacuerdo",0.33,IF(AL8="Muy en Desacuerdo",0.66,IF(AL8="Totalmente en Desacuerdo",1,"error")))))) -> -1 | AN8: Muy en Desacuerdo | AO8: =IF(AN8="Totalmente de Acuerdo",-1,IF(AN8="Muy de Acuerdo",-0.66,IF(AN8="Levemente de Acuerdo",-0.33,IF(AN8="Levemente en Desacuerdo",0.33,IF(AN8="Muy en Desacuerdo",0.66,IF(AN8="Totalmente en Desacuerdo",1,"error")))))) -> 0.66 | AP8: Muy de Acuerdo | AQ8: =IF(AP8="Totalmente de Acuerdo",-1,IF(AP8="Muy de Acuerdo",-0.66,IF(AP8="Levemente de Acuerdo",-0.33,IF(AP8="Levemente en Desacuerdo",0.33,IF(AP8="Muy en Desacuerdo",0.66,IF(AP8="Totalmente en Desacuerdo",1,"error")))))) -> -0.66 | AR8: Muy de Acuerdo | AS8: =IF(AR8="Totalmente de Acuerdo",1,IF(AR8="Muy de Acuerdo",0.66,IF(AR8="Levemente de Acuerdo",0.33,IF(AR8="Levemente en Desacuerdo",-0.33,IF(AR8="Muy en Desacuerdo",-0.66,IF(AR8="Totalmente en Desacuerdo",-1,"error")))))) -> 0.66 | AT8: Muy en Desacuerdo | AU8: =IF(AT8="Totalmente de Acuerdo",-1,IF(AT8="Muy de Acuerdo",-0.66,IF(AT8="Levemente de Acuerdo",-0.33,IF(AT8="Levemente en Desacuerdo",0.33,IF(AT8="Muy en Desacuerdo",0.66,IF(AT8="Totalmente en Desacuerdo",1,"error")))))) -> 0.66 | AV8: =+AU8+AS8+AQ8+AO8+AM8+AK8+AI8+AG8+AE8 -> -1.99 | AW8: Muy de Acuerdo | AX8: Muy de Acuerdo | AY8: Muy en Desacuerdo | AZ8: Levemente en Desacuerdo | BA8: Levemente en Desacuerdo | BB8: Levemente en Desacuerdo | BC8: Levemente en Desacuerdo | BD8: Levemente en Desacuerdo | BE8: Muy de Acuerdo | BF8: Muy de Acuerdo | BG8: Muy de Acuerdo | BH8: Me identifico | BI8: Me identifico | BJ8: Me identifico | BK8: Me identifico | BL8: Me identifico | BM8: Me identifico | BN8: Me identifico | BO8: Me identifico | BP8: Me identifico | BQ8: Me identifico | BR8: Me identifico | BS8: Me identifico | BT8: Me identifico | BU8: Me identifico | BV8: Me identifico | BW8: Me identifico | BX8: No asistí | BY8: En blanco | BZ8: En blanco
A9: 45547.903 | B9: 00344474148 | C9: 1999 | D9: Tercer año | E9: Varón | F9: Terciario completo | G9: Terciario completo | H9: Clase Media Alta (C2): entre $1.350.001 mensuales y $2.850.000 mensuales | I9: Trabajo propio | J9: Otra localidad en la Provincia de Córdoba | K9: , | L9: Muy en Desacuerdo | M9: =IF(L9="Totalmente de Acuerdo",-1,IF(L9="Muy de Acuerdo",-0.66,IF(L9="Levemente de Acuerdo",-0.33,IF(L9="Levemente en Desacuerdo",0.33,IF(L9="Muy en Desacuerdo",0.66,IF(L9="Totalmente en Desacuerdo",1,"error")))))) -> 0.66 | N9: Levemente de Acuerdo | O9: =IF(N9="Totalmente de Acuerdo",1,IF(N9="Muy de Acuerdo",0.66,IF(N9="Levemente de Acuerdo",0.33,IF(N9="Levemente en Desacuerdo",-0.33,IF(N9="Muy en Desacuerdo",-0.66,IF(N9="Totalmente en Desacuerdo",-1,"error")))))) -> 0.33 | P9: Levemente en Desacuerdo | Q9: =IF(P9="Totalmente de Acuerdo",-1,IF(P9="Muy de Acuerdo",-0.66,IF(P9="Levemente de Acuerdo",-0.33,IF(P9="Levemente en Desacuerdo",0.33,IF(P9="Muy en Desacuerdo",0.66,IF(P9="Totalmente en Desacuerdo",1,"error")))))) -> 0.33 | R9: Muy de Acuerdo | S9: =IF(R9="Totalmente de Acuerdo",1,IF(R9="Muy de Acuerdo",0.66,IF(R9="Levemente de Acuerdo",0.33,IF(R9="Levemente en Desacuerdo",-0.33,IF(R9="Muy en Desacuerdo",-0.66,IF(R9="Totalmente en Desacuerdo",-1,"error")))))) -> 0.66 | T9: Levemente de Acuerdo | U9: =IF(T9="Totalmente de Acuerdo",-1,IF(T9="Muy de Acuerdo",-0.66,IF(T9="Levemente de Acuerdo",-0.33,IF(T9="Levemente en Desacuerdo",0.33,IF(T9="Muy en Desacuerdo",0.66,IF(T9="Totalmente en Desacuerdo",1,"error")))))) -> -0.33 | V9: Totalmente de Acuerdo | W9: =IF(V9="Totalmente de Acuerdo",1,IF(V9="Muy de Acuerdo",0.66,IF(V9="Levemente de Acuerdo",0.33,IF(V9="Levemente en Desacuerdo",-0.33,IF(V9="Muy en Desacuerdo",-0.66,IF(V9="Totalmente en Desacuerdo",-1,"error")))))) -> 1 | X9: Muy de Acuerdo | Y9: =IF(X9="Totalmente de Acuerdo",1,IF(X9="Muy de Acuerdo",0.66,IF(X9="Levemente de Acuerdo",0.33,IF(X9="Levemente en Desacuerdo",-0.33,IF(X9="Muy en Desacuerdo",-0.66,IF(X9="Totalmente en Desacuerdo",-1,"error")))))) -> 0.66 | Z9: Levemente en Acuerdo | AA9: =IF(Z9="Totalmente de Acuerdo",1,IF(Z9="Muy de Acuerdo",0.66,IF(Z9="Levemente en Acuerdo",0.33,IF(Z9="Levemente en Desacuerdo",-0.33,IF(Z9="Muy en Desacuerdo",-0.66,IF(Z9="Totalmente en Desacuerdo",-1,"error")))))) -> 0.33 | AB9: =+AA9+Y9+W9+U9+S9+Q9+O9+M9 -> 3.64 | AC9: =+AB9*AB$29 -> 4.095 | AD9: Totalmente en Desacuerdo | AE9: =IF(AD9="Totalmente de Acuerdo",1,IF(AD9="Muy de Acuerdo",0.66,IF(AD9="Levemente de Acuerdo",0.33,IF(AD9="Levemente en Desacuerdo",-0.33,IF(AD9="Muy en Desacuerdo",-0.66,IF(AD9="Totalmente en Desacuerdo",-1,"error")))))) -> -1 | AF9: Muy de Acuerdo | AG9: =IF(AF9="Totalmente de Acuerdo",-1,IF(AF9="Muy de Acuerdo",-0.66,IF(AF9="Levemente de Acuerdo",-0.33,IF(AF9="Levemente en Desacuerdo",0.33,IF(AF9="Muy en Desacuerdo",0.66,IF(AF9="Totalmente en Desacuerdo",1,"error")))))) -> -0.66 | AH9: Levemente de Acuerdo | AI9: =IF(AH9="Totalmente de Acuerdo",1,IF(AH9="Muy de Acuerdo",0.66,IF(AH9="Levemente de Acuerdo",0.33,IF(AH9="Levemente en Desacuerdo",-0.33,IF(AH9="Muy en Desacuerdo",-0.66,IF(AH9="Totalmente en Desacuerdo",-1,"error")))))) -> 0.33 | AJ9: Muy en Desacuerdo | AK9: =IF(AJ9="Totalmente de Acuerdo",1,IF(AJ9="Muy de Acuerdo",0.66,IF(AJ9="Levemente de Acuerdo",0.33,IF(AJ9="Levemente en Desacuerdo",-0.33,IF(AJ9="Muy en Desacuerdo",-0.66,IF(AJ9="Totalmente en Desacuerdo",-1,"error")))))) -> -0.66 | AL9: Levemente de Acuerdo | AM9: =IF(AL9="Totalmente de Acuerdo",-1,IF(AL9="Muy de Acuerdo",-0.66,IF(AL9="Levemente de Acuerdo",-0.33,IF(AL9="Levemente en Desacuerdo",0.33,IF(AL9="Muy en Desacuerdo",0.66,IF(AL9="Totalmente en Desacuerdo",1,"error")))))) -> -0.33 | AN9: Muy en Desacuerdo | AO9: =IF(AN9="Totalmente de Acuerdo",-1,IF(AN9="Muy de Acuerdo",-0.66,IF(AN9="Levemente de Acuerdo",-0.33,IF(AN9="Levemente en Desacuerdo",0.33,IF(AN9="Muy en Desacuerdo",0.66,IF(AN9="Totalmente en Desacuerdo",1,"error")))))) -> 0.66 | AP9: Levemente de Acuerdo | AQ9: =IF(AP9="Totalmente de Acuerdo",-1,IF(AP9="Muy de Acuerdo",-0.66,IF(AP9="Levemente de Acuerdo",-0.33,IF(AP9="Levemente en Desacuerdo",0.33,IF(AP9="Muy en Desacuerdo",0.66,IF(AP9="Totalmente en Desacuerdo",1,"error")))))) -> -0.33 | AR9: Totalmente de Acuerdo | AS9: =IF(AR9="Totalmente de Acuerdo",1,IF(AR9="Muy de Acuerdo",0.66,IF(AR9="Levemente de Acuerdo",0.33,IF(AR9="Levemente en Desacuerdo",-0.33,IF(AR9="Muy en Desacuerdo",-0.66,IF(AR9="Totalmente en Desacuerdo",-1,"error")))))) -> 1 | AT9: Totalmente en Desacuerdo | AU9: =IF(AT9="Totalmente de Acuerdo",-1,IF(AT9="Muy de Acuerdo",-0.66,IF(AT9="Levemente de Acuerdo",-0.33,IF(AT9="Levemente en Desacuerdo",0.33,IF(AT9="Muy en Desacuerdo",0.66,IF(AT9="Totalmente en Desacuerdo",1,"error")))))) -> 1 | AV9: =+AU9+AS9+AQ9+AO9+AM9+AK9+AI9+AG9+AE9 -> 0.01 | AW9: Levemente de Acuerdo | AX9: Muy de Acuerdo | AY9: Levemente en Desacuerdo | AZ9: Totalmente en Desacuerdo | BA9: Totalmente en Desacuerdo | BB9: Totalmente de Acuerdo | BC9: Totalmente de Acuerdo | BD9: Totalmente de Acuerdo | BE9: Levemente en Desacuerdo | BF9: Muy en Desacuerdo | BG9: Muy en Desacuerdo | BH9: Me identifico | BX9: Javier Milei (La Libertad Avanza) | BY9: En blanco | BZ9: En blanco
A10: 45547.901 | B10: 004551455698171 | C10: 2001 | D10: Cuarto año | E10: Mujer | F10: Secundario incompleto | G10: Universitario completo | H10: Clase Alta (ABC1): más de $2.850.000 mensuales | I10: Familia | J10: Otra localidad en otra Provincia | K10: , | L10: Levemente de Acuerdo | M10: =IF(L10="Totalmente de Acuerdo",-1,IF(L10="Muy de Acuerdo",-0.66,IF(L10="Levemente de Acuerdo",-0.33,IF(L10="Levemente en Desacuerdo",0.33,IF(L10="Muy en Desacuerdo",0.66,IF(L10="Totalmente en Desacuerdo",1,"error")))))) -> -0.33 | N10: Levemente de Acuerdo | O10: =IF(N10="Totalmente de Acuerdo",1,IF(N10="Muy de Acuerdo",0.66,IF(N10="Levemente de Acuerdo",0.33,IF(N10="Levemente en Desacuerdo",-0.33,IF(N10="Muy en Desacuerdo",-0.66,IF(N10="Totalmente en Desacuerdo",-1,"error")))))) -> 0.33 | P10: Levemente de Acuerdo | Q10: =IF(P10="Totalmente de Acuerdo",-1,IF(P10="Muy de Acuerdo",-0.66,IF(P10="Levemente de Acuerdo",-0.33,IF(P10="Levemente en Desacuerdo",0.33,IF(P10="Muy en Desacuerdo",0.66,IF(P10="Totalmente en Desacuerdo",1,"error")))))) -> -0.33 | R10: Levemente de Acuerdo | S10: =IF(R10="Totalmente de Acuerdo",1,IF(R10="Muy de Acuerdo",0.66,IF(R10="Levemente de Acuerdo",0.33,IF(R10="Levemente en Desacuerdo",-0.33,IF(R10="Muy en Desacuerdo",-0.66,IF(R10="Totalmente en Desacuerdo",-1,"error")))))) -> 0.33 | T10: Levemente de Acuerdo | U10: =IF(T10="Totalmente de Acuerdo",-1,IF(T10="Muy de Acuerdo",-0.66,IF(T10="Levemente de Acuerdo",-0.33,IF(T10="Levemente en Desacuerdo",0.33,IF(T10="Muy en Desacuerdo",0.66,IF(T10="Totalmente en Desacuerdo",1,"error")))))) -> -0.33 | V10: Muy de Acuerdo | W10: =IF(V10="Totalmente de Acuerdo",1,IF(V10="Muy de Acuerdo",0.66,IF(V10="Levemente de Acuerdo",0.33,IF(V10="Levemente en Desacuerdo",-0.33,IF(V10="Muy en Desacuerdo",-0.66,IF(V10="Totalmente en Desacuerdo",-1,"error")))))) -> 0.66 | X10: Levemente de Acuerdo | Y10: =IF(X10="Totalmente de Acuerdo",1,IF(X10="Muy de Acuerdo",0.66,IF(X10="Levemente de Acuerdo",0.33,IF(X10="Levemente en Desacuerdo",-0.33,IF(X10="Muy en Desacuerdo",-0.66,IF(X10="Totalmente en Desacuerdo",-1,"error")))))) -> 0.33 | Z10: Levemente en Desacuerdo | AA10: =IF(Z10="Totalmente de Acuerdo",1,IF(Z10="Muy de Acuerdo",0.66,IF(Z10="Levemente en Acuerdo",0.33,IF(Z10="Levemente en Desacuerdo",-0.33,IF(Z10="Muy en Desacuerdo",-0.66,IF(Z10="Totalmente en Desacuerdo",-1,"error")))))) -> -0.33 | AB10: =+AA10+Y10+W10+U10+S10+Q10+O10+M10 -> 0.33 | AC10: =+AB10*AB$29 -> 0.37125 | AD10: Levemente en Desacuerdo | AE10: =IF(AD10="Totalmente de Acuerdo",1,IF(AD10="Muy de Acuerdo",0.66,IF(AD10="Levemente de Acuerdo",0.33,IF(AD10="Levemente en Desacuerdo",-0.33,IF(AD10="Muy en Desacuerdo",-0.66,IF(AD10="Totalmente en Desacuerdo",-1,"error")))))) -> -0.33 | AF10: Muy de Acuerdo | AG10: =IF(AF10="Totalmente de Acuerdo",-1,IF(AF10="Muy de Acuerdo",-0.66,IF(AF10="Levemente de Acuerdo",-0.33,IF(AF10="Levemente en Desacuerdo",0.33,IF(AF10="Muy en Desacuerdo",0.66,IF(AF10="Totalmente en Desacuerdo",1,"error")))))) -> -0.66 | AH10: Levemente en Desacuerdo | AI10: =IF(AH10="Totalmente de Acuerdo",1,IF(AH10="Muy de Acuerdo",0.66,IF(AH10="Levemente de Acuerdo",0.33,IF(AH10="Levemente en Desacuerdo",-0.33,IF(AH10="Muy en Desacuerdo",-0.66,IF(AH10="Totalmente en Desacuerdo",-1,"error")))))) -> -0.33 | AJ10: Levemente en Desacuerdo | AK10: =IF(AJ10="Totalmente de Acuerdo",1,IF(AJ10="Muy de Acuerdo",0.66,IF(AJ10="Levemente de Acuerdo",0.33,IF(AJ10="Levemente en Desacuerdo",-0.33,IF(AJ10="Muy en Desacuerdo",-0.66,IF(AJ10="Totalmente en Desacuerdo",-1,"error")))))) -> -0.33 | AL10: Muy de Acuerdo | AM10: =IF(AL10="Totalmente de Acuerdo",-1,IF(AL10="Muy de Acuerdo",-0.66,IF(AL10="Levemente de Acuerdo",-0.33,IF(AL10="Levemente en Desacuerdo",0.33,IF(AL10="Muy en Desacuerdo",0.66,IF(AL10="Totalmente en Desacuerdo",1,"error")))))) -> -0.66 | AN10: Totalmente en Desacuerdo | AO10: =IF(AN10="Totalmente de Acuerdo",-1,IF(AN10="Muy de Acuerdo",-0.66,IF(AN10="Levemente de Acuerdo",-0.33,IF(AN10="Levemente en Desacuerdo",0.33,IF(AN10="Muy en Desacuerdo",0.66,IF(AN10="Totalmente en Desacuerdo",1,"error")))))) -> 1 | AP10: Levemente de Acuerdo | AQ10: =IF(AP10="Totalmente de Acuerdo",-1,IF(AP10="Muy de Acuerdo",-0.66,IF(AP10="Levemente de Acuerdo",-0.33,IF(AP10="Levemente en Desacuerdo",0.33,IF(AP10="Muy en Desacuerdo",0.66,IF(AP10="Totalmente en Desacuerdo",1,"error")))))) -> -0.33 | AR10: Muy de Acuerdo | AS10: =IF(AR10="Totalmente de Acuerdo",1,IF(AR10="Muy de Acuerdo",0.66,IF(AR10="Levemente de Acuerdo",0.33,IF(AR10="Levemente en Desacuerdo",-0.33,IF(AR10="Muy en Desacuerdo",-0.66,IF(AR10="Totalmente en Desacuerdo",-1,"error")))))) -> 0.66 | AT10: Totalmente en Desacuerdo | AU10: =IF(AT10="Totalmente de Acuerdo",-1,IF(AT10="Muy de Acuerdo",-0.66,IF(AT10="Levemente de Acuerdo",-0.33,IF(AT10="Levemente en Desacuerdo",0.33,IF(AT10="Muy en Desacuerdo",0.66,IF(AT10="Totalmente en Desacuerdo",1,"error")))))) -> 1 | AV10: =+AU10+AS10+AQ10+AO10+AM10+AK10+AI10+AG10+AE10 -> 0.02 | AW10: Muy de Acuerdo | AX10: Levemente de Acuerdo | AY10: Muy en Desacuerdo | AZ10: Muy en Desacuerdo | BA10: Totalmente en Desacuerdo | BB10: Totalmente en Desacuerdo | BC10: Totalmente en Desacuerdo | BD10: Muy en Desacuerdo | BE10: Muy de Acuerdo | BF10: Levemente en Desacuerdo | BG10: Muy de Acuerdo | BO10: Me identifico | BX10: No vote | BY10: En blanco | BZ10: En blanco
A11: 45554.363 | B11: 00506717796 | C11: 2001 | D11: Cuarto año | E11: Mujer | F11: Universitario completo | G11: Universitario completo | H11: Clase Alta (ABC1): más de $2.850.000 mensuales | I11: Familia | J11: Ciudad de Córdoba | K11: , | L11: Levemente en Desacuerdo | M11: =IF(L11="Totalmente de Acuerdo",-1,IF(L11="Muy de Acuerdo",-0.66,IF(L11="Levemente de Acuerdo",-0.33,IF(L11="Levemente en Desacuerdo",0.33,IF(L11="Muy en Desacuerdo",0.66,IF(L11="Totalmente en Desacuerdo",1,"error")))))) -> 0.33 | N11: Levemente de Acuerdo | O11: =IF(N11="Totalmente de Acuerdo",1,IF(N11="Muy de Acuerdo",0.66,IF(N11="Levemente de Acuerdo",0.33,IF(N11="Levemente en Desacuerdo",-0.33,IF(N11="Muy en Desacuerdo",-0.66,IF(N11="Totalmente en Desacuerdo",-1,"error")))))) -> 0.33 | P11: Muy de Acuerdo | Q11: =IF(P11="Totalmente de Acuerdo",-1,IF(P11="Muy de Acuerdo",-0.66,IF(P11="Levemente de Acuerdo",-0.33,IF(P11="Levemente en Desacuerdo",0.33,IF(P11="Muy en Desacuerdo",0.66,IF(P11="Totalmente en Desacuerdo",1,"error")))))) -> -0.66 | R11: Levemente de Acuerdo | S11: =IF(R11="Totalmente de Acuerdo",1,IF(R11="Muy de Acuerdo",0.66,IF(R11="Levemente de Acuerdo",0.33,IF(R11="Levemente en Desacuerdo",-0.33,IF(R11="Muy en Desacuerdo",-0.66,IF(R11="Totalmente en Desacuerdo",-1,"error")))))) -> 0.33 | T11: Levemente en Desacuerdo | U11: =IF(T11="Totalmente de Acuerdo",-1,IF(T11="Muy de Acuerdo",-0.66,IF(T11="Levemente de Acuerdo",-0.33,IF(T11="Levemente en Desacuerdo",0.33,IF(T11="Muy en Desacuerdo",0.66,IF(T11="Totalmente en Desacuerdo",1,"error")))))) -> 0.33 | V11: Levemente en Desacuerdo | W11: =IF(V11="Totalmente de Acuerdo",1,IF(V11="Muy de Acuerdo",0.66,IF(V11="Levemente de Acuerdo",0.33,IF(V11="Levemente en Desacuerdo",-0.33,IF(V11="Muy en Desacuerdo",-0.66,IF(V11="Totalmente en Desacuerdo",-1,"error")))))) -> -0.33 | X11: Muy de Acuerdo | Y11: =IF(X11="Totalmente de Acuerdo",1,IF(X11="Muy de Acuerdo",0.66,IF(X11="Levemente de Acuerdo",0.33,IF(X11="Levemente en Desacuerdo",-0.33,IF(X11="Muy en Desacuerdo",-0.66,IF(X11="Totalmente en Desacuerdo",-1,"error")))))) -> 0.66 | Z11: Muy en Desacuerdo | AA11: =IF(Z11="Totalmente de Acuerdo",1,IF(Z11="Muy de Acuerdo",0.66,IF(Z11="Levemente en Acuerdo",0.33,IF(Z11="Levemente en Desacuerdo",-0.33,IF(Z11="Muy en Desacuerdo",-0.66,IF(Z11="Totalmente en Desacuerdo",-1,"error")))))) -> -0.66 | AB11: =+AA11+Y11+W11+U11+S11+Q11+O11+M11 -> 0.33 | AC11: =+AB11*AB$29 -> 0.37125 | AD11: Levemente en Desacuerdo | AE11: =IF(AD11="Totalmente de Acuerdo",1,IF(AD11="Muy de Acuerdo",0.66,IF(AD11="Levemente de Acuerdo",0.33,IF(AD11="Levemente en Desacuerdo",-0.33,IF(AD11="Muy en Desacuerdo",-0.66,IF(AD11="Totalmente en Desacuerdo",-1,"error")))))) -> -0.33 | AF11: Muy de Acuerdo | AG11: =IF(AF11="Totalmente de Acuerdo",-1,IF(AF11="Muy de Acuerdo",-0.66,IF(AF11="Levemente de Acuerdo",-0.33,IF(AF11="Levemente en Desacuerdo",0.33,IF(AF11="Muy en Desacuerdo",0.66,IF(AF11="Totalmente en Desacuerdo",1,"error")))))) -> -0.66 | AH11: Muy en Desacuerdo | AI11: =IF(AH11="Totalmente de Acuerdo",1,IF(AH11="Muy de Acuerdo",0.66,IF(AH11="Levemente de Acuerdo",0.33,IF(AH11="Levemente en Desacuerdo",-0.33,IF(AH11="Muy en Desacuerdo",-0.66,IF(AH11="Totalmente en Desacuerdo",-1,"error")))))) -> -0.66 | AJ11: Totalmente en Desacuerdo | AK11: =IF(AJ11="Totalmente de Acuerdo",1,IF(AJ11="Muy de Acuerdo",0.66,IF(AJ11="Levemente de Acuerdo",0.33,IF(AJ11="Levemente en Desacuerdo",-0.33,IF(AJ11="Muy en Desacuerdo",-0.66,IF(AJ11="Totalmente en Desacuerdo",-1,"error")))))) -> -1 | AL11: Levemente de Acuerdo | AM11: =IF(AL11="Totalmente de Acuerdo",-1,IF(AL11="Muy de Acuerdo",-0.66,IF(AL11="Levemente de Acuerdo",-0.33,IF(AL11="Levemente en Desacuerdo",0.33,IF(AL11="Muy en Desacuerdo",0.66,IF(AL11="Totalmente en Desacuerdo",1,"error")))))) -> -0.33 | AN11: Muy en Desacuerdo | AO11: =IF(AN11="Totalmente de Acuerdo",-1,IF(AN11="Muy de Acuerdo",-0.66,IF(AN11="Levemente de Acuerdo",-0.33,IF(AN11="Levemente en Desacuerdo",0.33,IF(AN11="Muy en Desacuerdo",0.66,IF(AN11="Totalmente en Desacuerdo",1,"error")))))) -> 0.66 | AP11: Levemente de Acuerdo | AQ11: =IF(AP11="Totalmente de Acuerdo",-1,IF(AP11="Muy de Acuerdo",-0.66,IF(AP11="Levemente de Acuerdo",-0.33,IF(AP11="Levemente en Desacuerdo",0.33,IF(AP11="Muy en Desacuerdo",0.66,IF(AP11="Totalmente en Desacuerdo",1,"error")))))) -> -0.33 | AR11: Muy de Acuerdo | AS11: =IF(AR11="Totalmente de Acuerdo",1,IF(AR11="Muy de Acuerdo",0.66,IF(AR11="Levemente de Acuerdo",0.33,IF(AR11="Levemente en Desacuerdo",-0.33,IF(AR11="Muy en Desacuerdo",-0.66,IF(AR11="Totalmente en Desacuerdo",-1,"error")))))) -> 0.66 | AT11: Totalmente en Desacuerdo | AU11: =IF(AT11="Totalmente de Acuerdo",-1,IF(AT11="Muy de Acuerdo",-0.66,IF(AT11="Levemente de Acuerdo",-0.33,IF(AT11="Levemente en Desacuerdo",0.33,IF(AT11="Muy en Desacuerdo",0.66,IF(AT11="Totalmente en Desacuerdo",1,"error")))))) -> 1 | AV11: =+AU11+AS11+AQ11+AO11+AM11+AK11+AI11+AG11+AE11 -> -0.99 | AW11: Muy de Acuerdo | AX11: Levemente de Acuerdo | AY11: Totalmente en Desacuerdo | AZ11: Muy en Desacuerdo | BA11: Totalmente en Desacuerdo | BB11: Levemente de Acuerdo | BC11: Levemente en Desacuerdo | BD11: Muy de Acuerdo | BE11: Totalmente de Acuerdo | BF11: Levemente en Desacuerdo | BG11: Levemente en Desacuerdo | BH11: Me identifico | BL11: Me identifico | BM11: Me identifico | BO11: Me identifico | BR11: Me identifico | BX11: Patricia Bullrich (Juntos por el Cambio) | BY11: Javier Milei (La Libertad Avanza) | BZ11: Javier Milei (La Libertad Avanza)
A12: 45551.791 | B12: 00513759005 | C12: 2002 | D12: Cuarto año | E12: Varón | F12: Posgrado completo | G12: Posgrado completo | H12: Clase Media Alta (C2): entre $1.350.001 mensuales y $2.850.000 mensuales | I12: Familia | J12: Ciudad de Córdoba | K12: , | L12: Muy en Desacuerdo | M12: =IF(L12="Totalmente de Acuerdo",-1,IF(L12="Muy de Acuerdo",-0.66,IF(L12="Levemente de Acuerdo",-0.33,IF(L12="Levemente en Desacuerdo",0.33,IF(L12="Muy en Desacuerdo",0.66,IF(L12="Totalmente en Desacuerdo",1,"error")))))) -> 0.66 | N12: Levemente en Desacuerdo | O12: =IF(N12="Totalmente de Acuerdo",1,IF(N12="Muy de Acuerdo",0.66,IF(N12="Levemente de Acuerdo",0.33,IF(N12="Levemente en Desacuerdo",-0.33,IF(N12="Muy en Desacuerdo",-0.66,IF(N12="Totalmente en Desacuerdo",-1,"error")))))) -> -0.33 | P12: Totalmente de Acuerdo | Q12: =IF(P12="Totalmente de Acuerdo",-1,IF(P12="Muy de Acuerdo",-0.66,IF(P12="Levemente de Acuerdo",-0.33,IF(P12="Levemente en Desacuerdo",0.33,IF(P12="Muy en Desacuerdo",0.66,IF(P12="Totalmente en Desacuerdo",1,"error")))))) -> -1 | R12: Muy de Acuerdo | S12: =IF(R12="Totalmente de Acuerdo",1,IF(R12="Muy de Acuerdo",0.66,IF(R12="Levemente de Acuerdo",0.33,IF(R12="Levemente en Desacuerdo",-0.33,IF(R12="Muy en Desacuerdo",-0.66,IF(R12="Totalmente en Desacuerdo",-1,"error")))))) -> 0.66 | T12: Levemente de Acuerdo | U12: =IF(T12="Totalmente de Acuerdo",-1,IF(T12="Muy de Acuerdo",-0.66,IF(T12="Levemente de Acuerdo",-0.33,IF(T12="Levemente en Desacuerdo",0.33,IF(T12="Muy en Desacuerdo",0.66,IF(T12="Totalmente en Desacuerdo",1,"error")))))) -> -0.33 | V12: Levemente de Acuerdo | W12: =IF(V12="Totalmente de Acuerdo",1,IF(V12="Muy de Acuerdo",0.66,IF(V12="Levemente de Acuerdo",0.33,IF(V12="Levemente en Desacuerdo",-0.33,IF(V12="Muy en Desacuerdo",-0.66,IF(V12="Totalmente en Desacuerdo",-1,"error")))))) -> 0.33 | X12: Levemente en Desacuerdo | Y12: =IF(X12="Totalmente de Acuerdo",1,IF(X12="Muy de Acuerdo",0.66,IF(X12="Levemente de Acuerdo",0.33,IF(X12="Levemente en Desacuerdo",-0.33,IF(X12="Muy en Desacuerdo",-0.66,IF(X12="Totalmente en Desacuerdo",-1,"error")))))) -> -0.33 | Z12: Totalmente en Desacuerdo | AA12: =IF(Z12="Totalmente de Acuerdo",1,IF(Z12="Muy de Acuerdo",0.66,IF(Z12="Levemente en Acuerdo",0.33,IF(Z12="Levemente en Desacuerdo",-0.33,IF(Z12="Muy en Desacuerdo",-0.66,IF(Z12="Totalmente en Desacuerdo",-1,"error")))))) -> -1 | AB12: =+AA12+Y12+W12+U12+S12+Q12+O12+M12 -> -1.34 | AC12: =+AB12*AB$29 -> -1.5075 | AD12: Levemente de Acuerdo | AE12: =IF(AD12="Totalmente de Acuerdo",1,IF(AD12="Muy de Acuerdo",0.66,IF(AD12="Levemente de Acuerdo",0.33,IF(AD12="Levemente en Desacuerdo",-0.33,IF(AD12="Muy en Desacuerdo",-0.66,IF(AD12="Totalmente en Desacuerdo",-1,"error")))))) -> 0.33 | AF12: Muy de Acuerdo | AG12: =IF(AF12="Totalmente de Acuerdo",-1,IF(AF12="Muy de Acuerdo",-0.66,IF(AF12="Levemente de Acuerdo",-0.33,IF(AF12="Levemente en Desacuerdo",0.33,IF(AF12="Muy en Desacuerdo",0.66,IF(AF12="Totalmente en Desacuerdo",1,"error")))))) -> -0.66 | AH12: Muy de Acuerdo | AI12: =IF(AH12="Totalmente de Acuerdo",1,IF(AH12="Muy de Acuerdo",0.66,IF(AH12="Levemente de Acuerdo",0.33,IF(AH12="Levemente en Desacuerdo",-0.33,IF(AH12="Muy en Desacuerdo",-0.66,IF(AH12="Totalmente en Desacuerdo",-1,"error")))))) -> 0.66 | AJ12: Totalmente de Acuerdo | AK12: =IF(AJ12="Totalmente de Acuerdo",1,IF(AJ12="Muy de Acuerdo",0.66,IF(AJ12="Levemente de Acuerdo",0.33,IF(AJ12="Levemente en Desacuerdo",-0.33,IF(AJ12="Muy en Desacuerdo",-0.66,IF(AJ12="Totalmente en Desacuerdo",-1,"error")))))) -> 1 | AL12: Muy de Acuerdo | AM12: =IF(AL12="Totalmente de Acuerdo",-1,IF(AL12="Muy de Acuerdo",-0.66,IF(AL12="Levemente de Acuerdo",-0.33,IF(AL12="Levemente en Desacuerdo",0.33,IF(AL12="Muy en Desacuerdo",0.66,IF(AL12="Totalmente en Desacuerdo",1,"error")))))) -> -0.66 | AN12: Muy de Acuerdo | AO12: =IF(AN12="Totalmente de Acuerdo",-1,IF(AN12="Muy de Acuerdo",-0.66,IF(AN12="Levemente de Acuerdo",-0.33,IF(AN12="Levemente en Desacuerdo",0.33,IF(AN12="Muy en Desacuerdo",0.66,IF(AN12="Totalmente en Desacuerdo",1,"error")))))) -> -0.66 | AP12: Totalmente de Acuerdo | AQ12: =IF(AP12="Totalmente de Acuerdo",-1,IF(AP12="Muy de Acuerdo",-0.66,IF(AP12="Levemente de Acuerdo",-0.33,IF(AP12="Levemente en Desacuerdo",0.33,IF(AP12="Muy en Desacuerdo",0.66,IF(AP12="Totalmente en Desacuerdo",1,"error")))))) -> -1 | AR12: Muy de Acuerdo | AS12: =IF(AR12="Totalmente de Acuerdo",1,IF(AR12="Muy de Acuerdo",0.66,IF(AR12="Levemente de Acuerdo",0.33,IF(AR12="Levemente en Desacuerdo",-0.33,IF(AR12="Muy en Desacuerdo",-0.66,IF(AR12="Totalmente en Desacuerdo",-1,"error")))))) -> 0.66 | AT12: Muy en Desacuerdo | AU12: =IF(AT12="Totalmente de Acuerdo",-1,IF(AT12="Muy de Acuerdo",-0.66,IF(AT12="Levemente de Acuerdo",-0.33,IF(AT12="Levemente en Desacuerdo",0.33,IF(AT12="Muy en Desacuerdo",0.66,IF(AT12="Totalmente en Desacuerdo",1,"error")))))) -> 0.66 | AV12: =+AU12+AS12+AQ12+AO12+AM12+AK12+AI12+AG12+AE12 -> 0.33 | AW12: Muy de Acuerdo | AX12: Muy de Acuerdo | AY12: Levemente de Acuerdo | AZ12: Levemente de Acuerdo | BA12: Muy en Desacuerdo | BB12: Levemente de Acuerdo | BC12: Levemente de Acuerdo | BD12: Levemente de Acuerdo | BE12: Muy en Desacuerdo | BF12: Muy de Acuerdo | BG12: Muy de Acuerdo | BL12: Me identifico | BX12: Javier Milei (La Libertad Avanza) | BY12: Patricia Bullrich (Juntos por el Cambio) | BZ12: Javier Milei (La Libertad Avanza)
