Workbook

Sheet regresion
A1: Número de Trámite DNI | B1: puntaje 1E | C1: puntaje 2E | D1: puntaje 3E | E1: puntaje 4E | F1: puntaje 5E | G1: puntaje 6E | H1: puntaje 7E | I1: puntaje 8E | K1: puntaje 1S | L1: puntaje 2S | M1: puntaje 3S | N1: puntaje 4S | O1: puntaje 5S | P1: puntaje 6S | Q1: puntaje 7S | R1: puntaje 8S | S1: puntaje 9S | U1: ¿Cómo votó para Presidente en el ballotage de noviembre de 2023? | V1: voto
A2: 00686630540 | B2: 1 | C2: 0.33 | D2: -0.66 | E2: 1 | F2: 0.66 | G2: 1 | H2: 1 | I2: -0.66 | K2: -0.33 | L2: -1 | M2: -0.33 | N2: -0.33 | O2: 0.66 | P2: 1 | Q2: 0.66 | R2: 1 | S2: 1 | U2: Javier Milei (La Libertad Avanza) | V2: =+IF(U2="Javier Milei (La Libertad Avanza)",1,0) -> 1
A3: 00164890275 | B3: -0.33 | C3: -0.66 | D3: -1 | E3: 0.33 | F3: 0.33 | G3: -0.33 | H3: -0.33 | I3: -0.66 | K3: 0.33 | L3: -0.33 | M3: -1 | N3: -1 | O3: -0.66 | P3: -0.66 | Q3: -0.66 | R3: -1 | S3: 1 | U3: Sergio Massa (Unión por la Patria) | V3: =+IF(U3="Javier Milei (La Libertad Avanza)",1,0) -> 0
A4: 00578280042 | B4: 0.33 | C4: -0.66 | D4: -0.66 | E4: 1 | F4: -0.33 | G4: 1 | H4: 0.66 | I4: -0.66 | K4: 1 | L4: -1 | M4: 0.33 | N4: -1 | O4: 0.33 | P4: 1 | Q4: 1 | R4: -0.33 | S4: 0.66 | U4: Javier Milei (La Libertad Avanza) | V4: =+IF(U4="Javier Milei (La Libertad Avanza)",1,0) -> 1
A5: 00464782483 | B5: -0.66 | C5: 0.33 | D5: -0.33 | E5: 0.33 | F5: -0.66 | G5: 0.66 | H5: 0.66 | I5: 0.33 | K5: 0.33 | L5: -1 | M5: 0.66 | N5: -1 | O5: -0.66 | P5: 0.33 | Q5: 0.33 | R5: 0.66 | S5: 0.33 | U5: Javier Milei (La Libertad Avanza) | V5: =+IF(U5="Javier Milei (La Libertad Avanza)",1,0) -> 1
A6: 00661842297 | B6: 0.33 | C6: -0.33 | D6: -0.66 | E6: 0.66 | F6: -0.33 | G6: -0.33 | H6: 0.33 | I6: -0.66 | K6: -0.66 | L6: 0.33 | M6: -0.33 | N6: -1 | O6: -0.66 | P6: -0.33 | Q6: 0.66 | R6: 0.66 | S6: -0.33 | U6: Sergio Massa (Unión por la Patria) | V6: =+IF(U6="Javier Milei (La Libertad Avanza)",1,0) -> 0
A7: 00623233790 | B7: 1 | C7: 0.66 | D7: -1 | E7: 1 | F7: 1 | G7: 1 | H7: -0.66 | I7: -0.66 | K7: -1 | L7: -1 | M7: -0.66 | N7: -1 | O7: -0.33 | P7: 1 | Q7: -1 | R7: 1 | S7: 1 | U7: Javier Milei (La Libertad Avanza) | V7: =+IF(U7="Javier Milei (La Libertad Avanza)",1,0) -> 1
A8: 00544287188 | B8: -0.33 | C8: 0.33 | D8: -0.66 | E8: 0.33 | F8: -0.33 | G8: 1 | H8: 0.33 | I8: -0.66 | K8: -0.66 | L8: -0.66 | M8: 0.33 | N8: -1 | O8: -1 | P8: 0.66 | Q8: -0.66 | R8: -0.66 | S8: 1 | U8: Javier Milei (La Libertad Avanza) | V8: =+IF(U8="Javier Milei (La Libertad Avanza)",1,0) -> 1
A9: 00305830361 | B9: -0.66 | C9: -0.33 | D9: -0.66 | E9: 0.66 | F9: 0.66 | G9: 0.66 | H9: -0.33 | I9: -0.66 | K9: -0.66 | L9: -0.66 | M9: -0.33 | N9: 0.33 | O9: -1 | P9: -0.33 | Q9: -0.66 | R9: 1 | S9: 0.66 | U9: En blanco | V9: =+IF(U9="Javier Milei (La Libertad Avanza)",1,0) -> 0
A10: 00712484148 | B10: -0.66 | C10: -0.66 | D10: -1 | E10: 0.33 | F10: 0.33 | G10: 0.33 | H10: -0.66 | I10: -1 | K10: -1 | L10: -0.66 | M10: -0.33 | N10: -1 | O10: -1 | P10: -0.66 | Q10: 0.66 | R10: 0.33 | S10: 1 | U10: Javier Milei (La Libertad Avanza) | V10: =+IF(U10="Javier Milei (La Libertad Avanza)",1,0) -> 1
A11: 006934766847656 | B11: 1 | C11: -1 | D11: -1 | E11: -1 | F11: -1 | G11: -0.66 | H11: 0.33 | I11: -1 | K11: -0.66 | L11: 1 | M11: -1 | N11: -1 | O11: -1 | P11: -1 | Q11: -1 | R11: -1 | S11: 1 | U11: Sergio Massa (Unión por la Patria) | V11: =+IF(U11="Javier Milei (La Libertad Avanza)",1,0) -> 0
A12: 00338374873 | B12: -0.33 | C12: -0.33 | D12: -0.66 | E12: 0.33 | F12: -0.33 | G12: 0.66 | H12: -0.33 | I12: -0.33 | K12: 0.33 | L12: -0.66 | M12: -1 | N12: -1 | O12: -0.33 | P12: 0.33 | Q12: -0.33 | R12: 0.66 | S12: 0.66 | U12: Javier Milei (La Libertad Avanza) | V12: =+IF(U12="Javier Milei (La Libertad Avanza)",1,0) -> 1
A13: 00576235027 | B13: 0.66 | C13: 0.33 | D13: -0.66 | E13: 0.33 | F13: -0.33 | G13: 0.33 | H13: 0.66 | I13: 0.33 | K13: 0.33 | L13: -0.66 | M13: 0.66 | N13: -0.66 | O13: 0.33 | P13: 1 | Q13: -0.33 | R13: 0.33 | S13: 1 | U13: Javier Milei (La Libertad Avanza) | V13: =+IF(U13="Javier Milei (La Libertad Avanza)",1,0) -> 1
... A31: 00284397411 | B31: -0.66 | C31: -0.66 | D31: -1 | E31: -1 | F31: -0.66 | G31: 0.33 | H31: -0.33 | I31: -1 | K31: -0.66 | L31: 0.66 | M31: -1 | N31: -1 | O31: -1 | P31: -0.33 | Q31: -0.66 | R31: -1 | S31: 0.33 | U31: Sergio Massa (Unión por la Patria) | V31: =+IF(U31="Javier Milei (La Libertad Avanza)",1,0) -> 0

Sheet prediccones
A1: voto | B1: P5E | C1: P7E | D1: predicciones.Ec | G1: voto | H1: P2S | I1: P7E | J1: predicciones.Tot | M1: voto | N1: predicciones.Tot | R1: voto | S1: predicciones.Ec | AA1: coef = 1,9 | AB1: coef = 2,1 | AH1: coef = -2 | AI1: coef = 1,85
A2: 1 | B2: 0.66 | C2: 1 | D2: 0.98044092 | G2: 1 | H2: -1 | I2: 1 | J2: 0.96976892 | M2: 0 | N2: 0.41166422 | O2: media | R2: 0 | S2: 0.62167917 | T2: media | Z2: voto | AA2: P5E | AB2: P7E | AC2: predicciones.Ec | AG2: voto | AH2: P2S | AI2: P7E | AJ2: predicciones.Tot
A3: 0 | B3: 0.33 | C3: -0.33 | D3: 0.62167917 | G3: 0 | H3: -0.33 | I3: -0.33 | J3: 0.41166422 | M3: 0 | N3: 0.38642571 | O3: =+AVERAGE(N2:N11) -> 0.41433543 | R3: 0 | S3: 0.64728114 | T3: =+AVERAGE(S2:S11) -> 0.4561862 | Z3: 0 | AA3: -1 | AB3: -0.66 | AC3: 0.059867636 | AG3: 0 | AH3: 0.66 | AI3: -0.33 | AJ3: 0.086620831
A4: 1 | B4: -0.33 | C4: 0.66 | D4: 0.78542135 | G4: 1 | H4: -1 | I4: 0.66 | J4: 0.94459349 | M4: 0 | N4: 0.57666162 | P4: min | Q4: =+MIN(N2:N11) -> 0.086620831 | R4: 0 | S4: 0.75618977 | U4: min | V4: =+MIN(S2:S11) -> 0.059867636 | Z4: 0 | AA4: -0.66 | AB4: -0.33 | AC4: 0.19639494 | AG4: 0 | AH4: 0.33 | AI4: -0.66 | AJ4: 0.090876888
A5: 1 | B5: -0.66 | C5: 0.66 | D5: 0.65978211 | G5: 1 | H5: -1 | I5: 0.66 | J5: 0.94459349 | M5: 0 | N5: 0.14004743 | O5: des | P5: max | Q5: =+MAX(N2:N11) -> 0.89564045 | R5: 0 | S5: 0.33568551 | T5: des | U5: max | V5: =+MAX(S2:S11) -> 0.78542135 | Z5: 0 | AA5: -0.66 | AB5: -0.33 | AC5: 0.19639494 | AG5: 0 | AH5: 1 | AI5: 0.33 | AJ5: 0.14004743
A6: 0 | B6: -0.33 | C6: 0.33 | D6: 0.64728114 | G6: 0 | H6: 0.33 | I6: 0.33 | J6: 0.38642571 | M6: 0 | N6: 0.8229057 | O6: =+_xlfn.STDEV.S(N2:N11) -> 0.29928449 | R6: 0 | S6: 0.64728114 | T6: =+_xlfn.STDEV.S(S2:S11) -> 0.26355224 | Z6: 1 | AA6: -0.33 | AB6: -0.33 | AC6: 0.31566637 | AD6: =+AVERAGE(AC3:AC13) -> 0.35899889 | AG6: 0 | AH6: 0.33 | AI6: -0.33 | AJ6: 0.15584988
A7: 1 | B7: 1 | C7: -0.66 | D7: 0.74949811 | G7: 1 | H7: -1 | I7: -0.66 | J7: 0.59433293 | M7: 0 | N7: 0.89564045 | R7: 0 | S7: 0.78542135 | Z7: 1 | AA7: -0.33 | AB7: -0.33 | AC7: 0.31566637 | AG7: 1 | AH7: 0.66 | AI7: 0.33 | AJ7: 0.2444315
A8: 1 | B8: -0.33 | C8: 0.33 | D8: 0.64728114 | G8: 1 | H8: -0.66 | I8: 0.33 | J8: 0.8229057 | M8: 0 | N8: 0.15584988 | R8: 0 | S8: 0.31566637 | Z8: 0 | AA8: -0.33 | AB8: -0.33 | AC8: 0.31566637 | AG8: 0 | AH8: 0.33 | AI8: 0.33 | AJ8: 0.38642571
A9: 0 | B9: 0.66 | C9: -0.33 | D9: 0.75618977 | G9: 0 | H9: -0.66 | I9: -0.33 | J9: 0.57666162 | M9: 0 | N9: 0.57666162 | R9: 0 | S9: 0.19639494 | Z9: 0 | AA9: -1 | AB9: 0.33 | AC9: 0.33568551 | AG9: 0 | AH9: -0.33 | AI9: -0.33 | AJ9: 0.41166422
A10: 1 | B10: 0.33 | C10: -0.66 | D10: 0.45171271 | G10: 1 | H10: -0.66 | I10: -0.66 | J10: 0.42446906 | M10: 0 | N10: 0.090876888 | R10: 0 | S10: 0.059867636 | Z10: 1 | AA10: 0.33 | AB10: -0.66 | AC10: 0.45171271 | AG10: 1 | AH10: -0.66 | AI10: -0.66 | AJ10: 0.42446906
A11: 0 | B11: -1 | C11: 0.33 | D11: 0.33568551 | G11: 0 | H11: 1 | I11: 0.33 | J11: 0.14004743 | M11: 0 | N11: 0.086620831 | R11: 0 | S11: 0.19639494 | Z11: 1 | AA11: -0.66 | AB11: 0.33 | AC11: 0.49297266 | AG11: 0 | AH11: -0.66 | AI11: -0.33 | AJ11: 0.57666162 | AK11: =+AVERAGE(AJ3:AJ12) -> 0.30937088
A12: 1 | B12: -0.33 | C12: -0.33 | D12: 0.31566637 | G12: 1 | H12: -0.66 | I12: -0.33 | J12: 0.57666162 | M12: 1 | N12: 0.96976892 | R12: 1 | S12: 0.98044092 | Z12: 0 | AA12: 0.33 | AB12: -0.33 | AC12: 0.62167917 | AG12: 0 | AH12: -0.66 | AI12: -0.33 | AJ12: 0.57666162
A13: 1 | B13: -0.33 | C13: 0.66 | D13: 0.78542135 | G13: 1 | H13: -0.66 | I13: 0.66 | J13: 0.89564045 | M13: 1 | N13: 0.94459349 | O13: media | R13: 1 | S13: 0.78542135 | T13: media | Z13: 0 | AA13: -0.33 | AB13: 0.33 | AC13: 0.64728114 | AG13: 1 | AH13: -0.66 | AI13: -0.33 | AJ13: 0.57666162
A14: 1 | B14: 0.66 | C14: 1 | D14: 0.98044092 | G14: 1 | H14: -0.66 | I14: 1 | J14: 0.94168584 | M14: 1 | N14: 0.94459349 | O14: =+AVERAGE(N12:N31) -> 0.79283228 | R14: 1 | S14: 0.65978211 | T14: =+AVERAGE(S12:S31) -> 0.7719069 | Z14: 1 | AA14: -0.33 | AB14: 0.33 | AC14: 0.64728114 | AG14: 1 | AH14: -0.66 | AI14: -0.33 | AJ14: 0.57666162
A15: 0 | B15: -0.33 | C15: 0.33 | D15: 0.64728114 | G15: 0 | H15: -0.66 | I15: 0.33 | J15: 0.8229057 | M15: 1 | N15: 0.59433293 | R15: 1 | S15: 0.74949811 | U15: min | V15: =+MIN(S12:S31) -> 0.31566637 | Z15: 0 | AA15: -0.33 | AB15: 0.33 | AC15: 0.64728114 | AG15: 1 | AH15: -1 | AI15: -0.66 | AJ15: 0.59433293
A16: 1 | B16: 0.66 | C16: 0.33 | D16: 0.9250323 | G16: 1 | H16: -0.66 | I16: 0.33 | J16: 0.8229057 | M16: 1 | N16: 0.8229057 | O16: des | R16: 1 | S16: 0.64728114 | T16: =+_xlfn.STDEV.S(S12:S31) -> 0.22260279 | U16: max | V16: =+MAX(S12:S31) -> 0.98044092 | Z16: 1 | AA16: -0.66 | AB16: 0.66 | AC16: 0.65978211 | AG16: 1 | AH16: 0.33 | AI16: 1 | AJ16: 0.68639214
A17: 1 | B17: -0.66 | C17: 0.33 | D17: 0.49297266 | G17: 1 | H17: 0.66 | I17: 0.33 | J17: 0.2444315 | M17: 1 | N17: 0.42446906 | O17: =+_xlfn.STDEV.S(N12:N31) -> 0.20691324 | R17: 1 | S17: 0.45171271 | Z17: 1 | AA17: 1 | AB17: -0.66 | AC17: 0.74949811 | AG17: 0 | AH17: -0.66 | AI17: 0.33 | AJ17: 0.8229057
A18: 1 | B18: -0.33 | C18: 0.66 | D18: 0.78542135 | G18: 1 | H18: -1 | I18: 0.66 | J18: 0.94459349 | M18: 1 | N18: 0.57666162 | R18: 1 | S18: 0.31566637 | Z18: 0 | AA18: 0.66 | AB18: -0.33 | AC18: 0.75618977 | AG18: 1 | AH18: -0.66 | AI18: 0.33 | AJ18: 0.8229057
A19: 1 | B19: 0.66 | C19: 1 | D19: 0.98044092 | G19: 1 | H19: -0.33 | I19: 1 | J19: 0.89241529 | M19: 1 | N19: 0.89564045 | O19: min | P19: =+MIN(N12:N31) -> 0.2444315 | R19: 1 | S19: 0.78542135 | Z19: 1 | AA19: -0.33 | AB19: 0.66 | AC19: 0.78542135 | AG19: 1 | AH19: -0.66 | AI19: 0.33 | AJ19: 0.8229057
A20: 1 | B20: 0.66 | C20: 1 | D20: 0.98044092 | G20: 1 | H20: -0.66 | I20: 1 | J20: 0.94168584 | M20: 1 | N20: 0.94168584 | O20: max | P20: =+MAX(N12:N31) -> 0.96976892 | R20: 1 | S20: 0.98044092 | Z20: 1 | AA20: -0.33 | AB20: 0.66 | AC20: 0.78542135 | AG20: 1 | AH20: -0.66 | AI20: 0.33 | AJ20: 0.8229057
A21: 0 | B21: -0.33 | C21: 0.66 | D21: 0.78542135 | G21: 0 | H21: -0.66 | I21: 0.66 | J21: 0.89564045 | M21: 1 | N21: 0.8229057 | R21: 1 | S21: 0.9250323 | Z21: 1 | AA21: -0.33 | AB21: 0.66 | AC21: 0.78542135 | AG21: 1 | AH21: -0.33 | AI21: 1 | AJ21: 0.89241529
A22: 1 | B22: 0.33 | C22: 1 | D22: 0.96371328 | G22: 1 | H22: 0.33 | I22: 1 | J22: 0.68639214 | M22: 1 | N22: 0.2444315 | R22: 1 | S22: 0.49297266 | Z22: 0 | AA22: -0.33 | AB22: 0.66 | AC22: 0.78542135 | AG22: 0 | AH22: -0.66 | AI22: 0.66 | AJ22: 0.89564045
A23: 1 | B23: -0.33 | C23: -0.33 | D23: 0.31566637 | G23: 1 | H23: -0.66 | I23: -0.33 | J23: 0.57666162 | M23: 1 | N23: 0.94459349 | R23: 1 | S23: 0.78542135 | Z23: 1 | AA23: 0.33 | AB23: 0.33 | AC23: 0.86732954 | AG23: 1 | AH23: -0.66 | AI23: 0.66 | AJ23: 0.89564045
A24: 0 | B24: -0.33 | C24: -0.33 | D24: 0.31566637 | G24: 0 | H24: 0.33 | I24: -0.33 | J24: 0.15584988 | M24: 1 | N24: 0.89241529 | R24: 1 | S24: 0.98044092 | Z24: 1 | AA24: -0.33 | AB24: 1 | AC24: 0.88172844 | AG24: 1 | AH24: -0.66 | AI24: 0.66 | AJ24: 0.89564045
A25: 1 | B25: -0.33 | C25: 1 | D25: 0.88172844 | G25: 1 | H25: -1 | I25: 1 | J25: 0.96976892 | M25: 1 | N25: 0.94168584 | R25: 1 | S25: 0.98044092 | Z25: 1 | AA25: 0.66 | AB25: 0.33 | AC25: 0.9250323 | AG25: 1 | AH25: -0.66 | AI25: 1 | AJ25: 0.94168584
A26: 0 | B26: -0.66 | C26: -0.33 | D26: 0.19639494 | G26: 0 | H26: -0.66 | I26: -0.33 | J26: 0.57666162 | M26: 1 | N26: 0.68639214 | R26: 1 | S26: 0.96371328 | Z26: 1 | AA26: 0.33 | AB26: 0.66 | AC26: 0.92877253 | AG26: 1 | AH26: -0.66 | AI26: 1 | AJ26: 0.94168584
A27: 1 | B27: 0.33 | C27: 0.66 | D27: 0.92877253 | G27: 1 | H27: -0.66 | I27: 0.66 | J27: 0.89564045 | M27: 1 | N27: 0.57666162 | R27: 1 | S27: 0.31566637 | Z27: 1 | AA27: 0.66 | AB27: 0.66 | AC27: 0.96095474 | AG27: 1 | AH27: -1 | AI27: 0.66 | AJ27: 0.94459349
A28: 1 | B28: 0.66 | C28: 0.66 | D28: 0.96095474 | G28: 1 | H28: -1 | I28: 0.66 | J28: 0.94459349 | M28: 1 | N28: 0.96976892 | R28: 1 | S28: 0.88172844 | Z28: 1 | AA28: 0.33 | AB28: 1 | AC28: 0.96371328 | AG28: 1 | AH28: -1 | AI28: 0.66 | AJ28: 0.94459349
A29: 1 | B29: 0.33 | C29: 0.33 | D29: 0.86732954 | G29: 1 | H29: -0.66 | I29: 0.33 | J29: 0.8229057 | M29: 1 | N29: 0.89564045 | R29: 1 | S29: 0.92877253 | Z29: 1 | AA29: 0.66 | AB29: 1 | AC29: 0.98044092 | AG29: 1 | AH29: -1 | AI29: 0.66 | AJ29: 0.94459349
A30: 0 | B30: -1 | C30: -0.66 | D30: 0.059867636 | G30: 0 | H30: 0.33 | I30: -0.66 | J30: 0.090876888 | M30: 1 | N30: 0.94459349 | R30: 1 | S30: 0.96095474 | Z30: 1 | AA30: 0.66 | AB30: 1 | AC30: 0.98044092 | AG30: 1 | AH30: -1 | AI30: 0.66 | AJ30: 0.94459349
A31: 0 | B31: -0.66 | C31: -0.33 | D31: 0.19639494 | G31: 0 | H31: 0.66 | I31: -0.33 | J31: 0.086620831 | M31: 1 | N31: 0.8229057 | R31: 1 | S31: 0.86732954 | Z31: 1 | AA31: 0.66 | AB31: 1 | AC31: 0.98044092 | AG31: 1 | AH31: -1 | AI31: 1 | AJ31: 0.96976892
Z32: 1 | AA32: 0.66 | AB32: 1 | AC32: 0.98044092 | AG32: 1 | AH32: -1 | AI32: 1 | AJ32: 0.96976892

Sheet regresion3
A1: Número de Trámite DNI | B1: voto | C1: puntaje 1E | D1: puntaje 2E | E1: puntaje 3E | F1: puntaje 4E | G1: puntaje 5E | H1: puntaje 6E | I1: puntaje 7E | J1: puntaje 8E | L1: puntaje 1S | M1: puntaje 2S | N1: puntaje 3S | O1: puntaje 4S | P1: puntaje 5S | Q1: puntaje 6S | R1: puntaje 7S | S1: puntaje 8S | T1: puntaje 9S
A2: 00686630540 | B2: 1 | C2: =+dato3!M2 -> 1 | D2: =+dato3!O2 -> 0 | E2: =+dato3!Q2 -> -0.5 | F2: =+dato3!S2 -> 1 | G2: =+dato3!U2 -> 0.5 | H2: =+dato3!W2 -> 1 | I2: =+dato3!Y2 -> 1 | J2: =+dato3!AA2 -> -0.5 | L2: =+dato3!AE2 -> 0 | M2: =+dato3!AG2 -> -1 | N2: =+dato3!AI2 -> 0 | O2: =+dato3!AK2 -> 0 | P2: =+dato3!AM2 -> 0.5 | Q2: =+dato3!AO2 -> 1 | R2: =+dato3!AQ2 -> 0.5 | S2: =+dato3!AS2 -> 1 | T2: =+dato3!AU2 -> 1
A3: 00164890275 | B3: 0 | C3: =+dato3!M3 -> 0 | D3: =+dato3!O3 -> -0.5 | E3: =+dato3!Q3 -> -1 | F3: =+dato3!S3 -> 0 | G3: =+dato3!U3 -> 0 | H3: =+dato3!W3 -> 0 | I3: =+dato3!Y3 -> 0 | J3: =+dato3!AA3 -> -0.5 | L3: =+dato3!AE3 -> 0 | M3: =+dato3!AG3 -> 0 | N3: =+dato3!AI3 -> -1 | O3: =+dato3!AK3 -> -1 | P3: =+dato3!AM3 -> -0.5 | Q3: =+dato3!AO3 -> -0.5 | R3: =+dato3!AQ3 -> -0.5 | S3: =+dato3!AS3 -> -1 | T3: =+dato3!AU3 -> 1
A4: 00578280042 | B4: 1 | C4: =+dato3!M4 -> 0 | D4: =+dato3!O4 -> -0.5 | E4: =+dato3!Q4 -> -0.5 | F4: =+dato3!S4 -> 1 | G4: =+dato3!U4 -> 0 | H4: =+dato3!W4 -> 1 | I4: =+dato3!Y4 -> 0.5 | J4: =+dato3!AA4 -> -0.5 | L4: =+dato3!AE4 -> 1 | M4: =+dato3!AG4 -> -1 | N4: =+dato3!AI4 -> 0 | O4: =+dato3!AK4 -> -1 | P4: =+dato3!AM4 -> 0 | Q4: =+dato3!AO4 -> 1 | R4: =+dato3!AQ4 -> 1 | S4: =+dato3!AS4 -> 0 | T4: =+dato3!AU4 -> 0.5
A5: 00464782483 | B5: 1 | C5: =+dato3!M5 -> -0.5 | D5: =+dato3!O5 -> 0 | E5: =+dato3!Q5 -> 0 | F5: =+dato3!S5 -> 0 | G5: =+dato3!U5 -> -0.5 | H5: =+dato3!W5 -> 0.5 | I5: =+dato3!Y5 -> 0.5 | J5: =+dato3!AA5 -> 0 | L5: =+dato3!AE5 -> 0 | M5: =+dato3!AG5 -> -1 | N5: =+dato3!AI5 -> 0.5 | O5: =+dato3!AK5 -> -1 | P5: =+dato3!AM5 -> -0.5 | Q5: =+dato3!AO5 -> 0 | R5: =+dato3!AQ5 -> 0 | S5: =+dato3!AS5 -> 0.5 | T5: =+dato3!AU5 -> 0
A6: 00661842297 | B6: 0 | C6: =+dato3!M6 -> 0 | D6: =+dato3!O6 -> 0 | E6: =+dato3!Q6 -> -0.5 | F6: =+dato3!S6 -> 0.5 | G6: =+dato3!U6 -> 0 | H6: =+dato3!W6 -> 0 | I6: =+dato3!Y6 -> 0 | J6: =+dato3!AA6 -> -0.5 | L6: =+dato3!AE6 -> -0.5 | M6: =+dato3!AG6 -> 0 | N6: =+dato3!AI6 -> 0 | O6: =+dato3!AK6 -> -1 | P6: =+dato3!AM6 -> -0.5 | Q6: =+dato3!AO6 -> 0 | R6: =+dato3!AQ6 -> 0.5 | S6: =+dato3!AS6 -> 0.5 | T6: =+dato3!AU6 -> 0
A7: 00623233790 | B7: 1 | C7: =+dato3!M7 -> 1 | D7: =+dato3!O7 -> 0.5 | E7: =+dato3!Q7 -> -1 | F7: =+dato3!S7 -> 1 | G7: =+dato3!U7 -> 1 | H7: =+dato3!W7 -> 1 | I7: =+dato3!Y7 -> -0.5 | J7: =+dato3!AA7 -> -0.5 | L7: =+dato3!AE7 -> -1 | M7: =+dato3!AG7 -> -1 | N7: =+dato3!AI7 -> -0.5 | O7: =+dato3!AK7 -> -1 | P7: =+dato3!AM7 -> 0 | Q7: =+dato3!AO7 -> 1 | R7: =+dato3!AQ7 -> -1 | S7: =+dato3!AS7 -> 1 | T7: =+dato3!AU7 -> 1
A8: 00544287188 | B8: 1 | C8: =+dato3!M8 -> 0 | D8: =+dato3!O8 -> 0 | E8: =+dato3!Q8 -> -0.5 | F8: =+dato3!S8 -> 0 | G8: =+dato3!U8 -> 0 | H8: =+dato3!W8 -> 1 | I8: =+dato3!Y8 -> 0 | J8: =+dato3!AA8 -> -0.5 | L8: =+dato3!AE8 -> -0.5 | M8: =+dato3!AG8 -> -0.5 | N8: =+dato3!AI8 -> 0 | O8: =+dato3!AK8 -> -1 | P8: =+dato3!AM8 -> -1 | Q8: =+dato3!AO8 -> 0.5 | R8: =+dato3!AQ8 -> -0.5 | S8: =+dato3!AS8 -> -0.5 | T8: =+dato3!AU8 -> 1
A9: 00305830361 | B9: 0 | C9: =+dato3!M9 -> -0.5 | D9: =+dato3!O9 -> 0 | E9: =+dato3!Q9 -> -0.5 | F9: =+dato3!S9 -> 0.5 | G9: =+dato3!U9 -> 0.5 | H9: =+dato3!W9 -> 0.5 | I9: =+dato3!Y9 -> 0 | J9: =+dato3!AA9 -> -0.5 | L9: =+dato3!AE9 -> -0.5 | M9: =+dato3!AG9 -> -0.5 | N9: =+dato3!AI9 -> 0 | O9: =+dato3!AK9 -> 0 | P9: =+dato3!AM9 -> -1 | Q9: =+dato3!AO9 -> 0 | R9: =+dato3!AQ9 -> -0.5 | S9: =+dato3!AS9 -> 1 | T9: =+dato3!AU9 -> 0.5
A10: 00712484148 | B10: 1 | C10: =+dato3!M10 -> -0.5 | D10: =+dato3!O10 -> -0.5 | E10: =+dato3!Q10 -> -1 | F10: =+dato3!S10 -> 0 | G10: =+dato3!U10 -> 0 | H10: =+dato3!W10 -> 0 | I10: =+dato3!Y10 -> -0.5 | J10: =+dato3!AA10 -> -1 | L10: =+dato3!AE10 -> -1 | M10: =+dato3!AG10 -> -0.5 | N10: =+dato3!AI10 -> 0 | O10: =+dato3!AK10 -> -1 | P10: =+dato3!AM10 -> -1 | Q10: =+dato3!AO10 -> -0.5 | R10: =+dato3!AQ10 -> 0.5 | S10: =+dato3!AS10 -> 0 | T10: =+dato3!AU10 -> 1
A11: 006934766847656 | B11: 0 | C11: =+dato3!M11 -> 1 | D11: =+dato3!O11 -> -1 | E11: =+dato3!Q11 -> -1 | F11: =+dato3!S11 -> -1 | G11: =+dato3!U11 -> -1 | H11: =+dato3!W11 -> -0.5 | I11: =+dato3!Y11 -> 0 | J11: =+dato3!AA11 -> -1 | L11: =+dato3!AE11 -> -0.5 | M11: =+dato3!AG11 -> 1 | N11: =+dato3!AI11 -> -1 | O11: =+dato3!AK11 -> -1 | P11: =+dato3!AM11 -> -1 | Q11: =+dato3!AO11 -> -1 | R11: =+dato3!AQ11 -> -1 | S11: =+dato3!AS11 -> -1 | T11: =+dato3!AU11 -> 1
A12: 00338374873 | B12: 1 | C12: =+dato3!M12 -> 0 | D12: =+dato3!O12 -> 0 | E12: =+dato3!Q12 -> -0.5 | F12: =+dato3!S12 -> 0 | G12: =+dato3!U12 -> 0 | H12: =+dato3!W12 -> 0.5 | I12: =+dato3!Y12 -> 0 | J12: =+dato3!AA12 -> 0 | L12: =+dato3!AE12 -> 0 | M12: =+dato3!AG12 -> -0.5 | N12: =+dato3!AI12 -> -1 | O12: =+dato3!AK12 -> -1 | P12: =+dato3!AM12 -> 0 | Q12: =+dato3!AO12 -> 0 | R12: =+dato3!AQ12 -> 0 | S12: =+dato3!AS12 -> 0.5 | T12: =+dato3!AU12 -> 0.5
A13: 00576235027 | B13: 1 | C13: =+dato3!M13 -> 0.5 | D13: =+dato3!O13 -> 0 | E13: =+dato3!Q13 -> -0.5 | F13: =+dato3!S13 -> 0 | G13: =+dato3!U13 -> 0 | H13: =+dato3!W13 -> 0 | I13: =+dato3!Y13 -> 0.5 | J13: =+dato3!AA13 -> 0 | L13: =+dato3!AE13 -> 0 | M13: =+dato3!AG13 -> -0.5 | N13: =+dato3!AI13 -> 0.5 | O13: =+dato3!AK13 -> -0.5 | P13: =+dato3!AM13 -> 0 | Q13: =+dato3!AO13 -> 1 | R13: =+dato3!AQ13 -> 0 | S13: =+dato3!AS13 -> 0 | T13: =+dato3!AU13 -> 1
... A31: 00284397411 | B31: 0 | C31: =+dato3!M31 -> -0.5 | D31: =+dato3!O31 -> -0.5 | E31: =+dato3!Q31 -> -1 | F31: =+dato3!S31 -> -1 | G31: =+dato3!U31 -> -0.5 | H31: =+dato3!W31 -> 0 | I31: =+dato3!Y31 -> 0 | J31: =+dato3!AA31 -> -1 | L31: =+dato3!AE31 -> -0.5 | M31: =+dato3!AG31 -> 0.5 | N31: =+dato3!AI31 -> -1 | O31: =+dato3!AK31 -> -1 | P31: =+dato3!AM31 -> -1 | Q31: =+dato3!AO31 -> 0 | R31: =+dato3!AQ31 -> -0.5 | S31: =+dato3!AS31 -> -1 | T31: =+dato3!AU31 -> 0

Sheet predicciones3
A1: voto | B1: P5E | C1: P7E | D1: predicciones.Ec | F1: voto | G1: P2S | H1: P7E | I1: predicciones.Tot | N1: coef= -2,6 | O1: coef = 2 | T1: coef = 2 | U1: coef = 2,2
A2: 1 | B2: 0.5 | C2: 1 | D2: 0.97545455 | F2: 1 | G2: -1 | H2: 1 | I2: 0.98356854 | M2: voto | N2: P2S | O2: P7E | P2: predicciones.Tot | S2: voto | T2: P5E | U2: P7E | V2: predicciones.Ec | Y2: voto | Z2: P1E | AA2: P2E | AB2: P3E | AC2: P4E | AD2: P5E | AE2: P6E | AF2: P7E | AG2: P8E | AH2: predicciones
A3: 0 | B3: 0 | C3: 0 | D3: 0.58791929 | F3: 0 | G3: 0 | H3: 0 | I3: 0.36116576 | M3: 0 | N3: 1 | O3: 0 | P3: 0.039494625 | S3: 0 | T3: 0 | U3: 0 | V3: 0.58791929 | Y3: 0 | Z3: 0 | AA3: -0.5 | AB3: -1 | AC3: 0 | AD3: 0 | AE3: 0 | AF3: 0 | AG3: -0.5 | AH3: 0.48101905
A4: 1 | B4: 0 | C4: 0.5 | D4: 0.81667823 | F4: 1 | G4: -1 | H4: 0.5 | I4: 0.95569471 | M4: 0 | N4: 0.5 | O4: 0 | P4: 0.13229684 | S4: 0 | T4: 0 | U4: 0 | V4: 0.58791929 | Y4: 0 | Z4: 0 | AA4: 0 | AB4: -0.5 | AC4: 0.5 | AD4: 0 | AE4: 0 | AF4: 0 | AG4: -0.5 | AH4: 0.67659946
A5: 1 | B5: -0.5 | C5: 0.5 | D5: 0.60927342 | F5: 1 | G5: -1 | H5: 0.5 | I5: 0.95569471 | M5: 0 | N5: 0 | O5: -0.5 | P5: 0.16924841 | S5: 0 | T5: 0.5 | U5: 0 | V5: 0.80299408 | Y5: 0 | Z5: -0.5 | AA5: 0 | AB5: -0.5 | AC5: 0.5 | AD5: 0.5 | AE5: 0.5 | AF5: 0 | AG5: -0.5 | AH5: 0.77371147
A6: 0 | B6: 0 | C6: 0 | D6: 0.58791929 | F6: 0 | G6: 0 | H6: 0 | I6: 0.36116576 | M6: 0 | N6: 0 | O6: 0 | P6: 0.36116576 | S6: 0 | T6: -1 | U6: 0 | V6: 0.1487909 | Y6: 0 | Z6: 1 | AA6: -1 | AB6: -1 | AC6: -1 | AD6: -1 | AE6: -0.5 | AF6: 0 | AG6: -1 | AH6: 0.049727858 | AI6: =+AVERAGE(AH3:AH12) -> 0.41659273
A7: 1 | B7: 1 | C7: -0.5 | D7: 0.78855294 | F7: 1 | G7: -1 | H7: -0.5 | I7: 0.73692049 | M7: 0 | N7: 0 | O7: 0 | P7: 0.36116576 | Q7: =+AVERAGE(P3:P12) -> 0.43089613 | S7: 0 | T7: 0 | U7: 0 | V7: 0.58791929 | W7: =+AVERAGE(V3:V12) -> 0.48392755 | Y7: 0 | Z7: 0 | AA7: 0 | AB7: 0 | AC7: 0 | AD7: 0 | AE7: 0.5 | AF7: 0 | AG7: 0 | AH7: 0.16472469
A8: 1 | B8: 0 | C8: 0 | D8: 0.58791929 | F8: 1 | G8: -0.5 | H8: 0 | I8: 0.67703642 | M8: 0 | N8: 0 | O8: 0 | P8: 0.36116576 | S8: 0 | T8: 0 | U8: 0.5 | V8: 0.81667823 | Y8: 0 | Z8: 0.5 | AA8: 0 | AB8: 0 | AC8: 0.5 | AD8: 0 | AE8: 1 | AF8: 0.5 | AG8: 0 | AH8: 0.73357306
A9: 0 | B9: 0.5 | C9: 0 | D9: 0.80299408 | F9: 0 | G9: -0.5 | H9: 0 | I9: 0.67703642 | M9: 0 | N9: -0.5 | O9: 0 | P9: 0.67703642 | S9: 0 | T9: 0 | U9: 0 | V9: 0.58791929 | Y9: 0 | Z9: 0 | AA9: 0 | AB9: -0.5 | AC9: 0.5 | AD9: 0 | AE9: 0 | AF9: 0 | AG9: 0 | AH9: 0.52402848
A10: 1 | B10: 0 | C10: -0.5 | D10: 0.31361741 | F10: 1 | G10: -0.5 | H10: -0.5 | I10: 0.4303386 | M10: 0 | N10: -0.5 | O10: 0 | P10: 0.67703642 | S10: 0 | T10: -0.5 | U10: 0 | V10: 0.33306105 | Y10: 0 | Z10: -0.5 | AA10: 0 | AB10: -0.5 | AC10: 0 | AD10: -0.5 | AE10: 0.5 | AF10: 0 | AG10: -0.5 | AH10: 0.46311987
A11: 0 | B11: -1 | C11: 0 | D11: 0.1487909 | F11: 0 | G11: 1 | H11: 0 | I11: 0.039494625 | M11: 0 | N11: -0.5 | O11: 0 | P11: 0.67703642 | S11: 0 | T11: -1 | U11: -0.5 | V11: 0.053013029 | Y11: 0 | Z11: -1 | AA11: -1 | AB11: -1 | AC11: -0.5 | AD11: -1 | AE11: 0 | AF11: -0.5 | AG11: -1 | AH11: 0.019544374
A12: 1 | B12: 0 | C12: 0 | D12: 0.58791929 | F12: 1 | G12: -0.5 | H12: 0 | I12: 0.67703642 | M12: 0 | N12: -0.5 | O12: 0.5 | P12: 0.85331494 | S12: 0 | T12: -0.5 | U12: 0 | V12: 0.33306105 | Y12: 0 | Z12: -0.5 | AA12: -0.5 | AB12: -1 | AC12: -1 | AD12: -0.5 | AE12: 0 | AF12: 0 | AG12: -1 | AH12: 0.27987896
A13: 1 | B13: 0 | C13: 0.5 | D13: 0.81667823 | F13: 1 | G13: -0.5 | H13: 0.5 | I13: 0.85331494 | M13: 1 | N13: 0.5 | O13: 0 | P13: 0.13229684 | S13: 1 | T13: 0.5 | U13: 1 | V13: 0.97545455 | Y13: 1 | Z13: 1 | AA13: 0 | AB13: -0.5 | AC13: 1 | AD13: 0.5 | AE13: 1 | AF13: 1 | AG13: -0.5 | AH13: 0.9967846
A14: 1 | B14: 0.5 | C14: 1 | D14: 0.97545455 | F14: 1 | G14: -0.5 | H14: 1 | I14: 0.94166768 | M14: 1 | N14: -0.5 | O14: -0.5 | P14: 0.4303386 | S14: 1 | T14: 0 | U14: 0.5 | V14: 0.81667823 | Y14: 1 | Z14: 0 | AA14: -0.5 | AB14: -0.5 | AC14: 1 | AD14: 0 | AE14: 1 | AF14: 0.5 | AG14: -0.5 | AH14: 0.90591462
A15: 0 | B15: 0 | C15: 0 | D15: 0.58791929 | F15: 0 | G15: -0.5 | H15: 0 | I15: 0.67703642 | M15: 1 | N15: -0.5 | O15: 0 | P15: 0.67703642 | S15: 1 | T15: -0.5 | U15: 0.5 | V15: 0.60927342 | Y15: 1 | Z15: -0.5 | AA15: 0 | AB15: 0 | AC15: 0 | AD15: -0.5 | AE15: 0.5 | AF15: 0.5 | AG15: 0 | AH15: 0.57460489
A16: 1 | B16: 0.5 | C16: 0 | D16: 0.80299408 | F16: 1 | G16: -0.5 | H16: 0 | I16: 0.67703642 | M16: 1 | N16: -0.5 | O16: 0 | P16: 0.67703642 | S16: 1 | T16: 1 | U16: -0.5 | V16: 0.78855294 | Y16: 1 | Z16: 1 | AA16: 0.5 | AB16: -1 | AC16: 1 | AD16: 1 | AE16: 1 | AF16: -0.5 | AG16: -0.5 | AH16: 0.87480213
A17: 1 | B17: -0.5 | C17: 0 | D17: 0.33306105 | F17: 1 | G17: 0.5 | H17: 0 | I17: 0.13229684 | M17: 1 | N17: -0.5 | O17: 0 | P17: 0.67703642 | S17: 1 | T17: 0 | U17: 0 | V17: 0.58791929 | Y17: 1 | Z17: 0 | AA17: 0 | AB17: -0.5 | AC17: 0 | AD17: 0 | AE17: 1 | AF17: 0 | AG17: -0.5 | AH17: 0.51569494
A18: 1 | B18: 0 | C18: 0.5 | D18: 0.81667823 | F18: 1 | G18: -1 | H18: 0.5 | I18: 0.95569471 | M18: 1 | N18: -0.5 | O18: 0 | P18: 0.67703642 | S18: 1 | T18: 0 | U18: -0.5 | V18: 0.31361741 | Y18: 1 | Z18: -0.5 | AA18: -0.5 | AB18: -1 | AC18: 0 | AD18: 0 | AE18: 0 | AF18: -0.5 | AG18: -1 | AH18: 0.19074933
A19: 1 | B19: 0.5 | C19: 1 | D19: 0.97545455 | F19: 1 | G19: 0 | H19: 1 | I19: 0.81320974 | M19: 1 | N19: -0.5 | O19: 0 | P19: 0.67703642 | S19: 1 | T19: 0 | U19: 0 | V19: 0.58791929 | Y19: 1 | Z19: 0 | AA19: 0 | AB19: -0.5 | AC19: 0 | AD19: 0 | AE19: 0.5 | AF19: 0 | AG19: 0 | AH19: 0.36298186
... A31: 0 | B31: -0.5 | C31: 0 | D31: 0.33306105 | F31: 0 | G31: 0.5 | H31: 0 | I31: 0.13229684 | M31: 1 | N31: -1 | O31: 1 | P31: 0.98356854 | S31: 1 | T31: 0.5 | U31: 0.5 | V31: 0.9271522 | Y31: 1 | Z31: 0.5 | AA31: 1 | AB31: 1 | AC31: 0.5 | AD31: 0.5 | AE31: -0.5 | AF31: 0.5 | AG31: -0.5 | AH31: 0.9181353
M32: 1 | N32: -1 | O32: 1 | P32: 0.98356854 | S32: 1 | T32: 0 | U32: 0 | V32: 0.58791929 | Y32: 1 | Z32: 0 | AA32: 0 | AB32: -1 | AC32: 0.5 | AD32: 0 | AE32: 0 | AF32: 0 | AG32: -0.5 | AH32: 0.85805499

Sheet dato
L1: Eje economico | AD1: Eje Social
A2: Marca temporal | B2: Número de Trámite DNI | C2: Año de nacimiento | D2: Año de cursado. La mayoría de las materias obligatorias que cursaste en 2024 son de: | E2: ¿Con qué identidad de género se identifica? | F2: ¿Cuál fue el último nivel educativo alcanzado por su padre o tutor? | G2: ¿Cuál fue el último nivel educativo alcanzado por su madre o tutora? | H2: Ubíquese en la pirámide en base a su ingreso total familiar aproximado | I2: ¿De dónde provienen tus ingresos? | J2: ¿Dónde vivías antes de venir a estudiar a Córdoba? | K2: . | L2: El Estado debe intervenir en el mercado laboral para reducir la brecha salarial entre hombres y mujeres | M2: puntaje 1E | N2: Los países con Estados más “pequeños” (menor gasto público) son más exitosos y sus habitantes gozan de una mejor calidad de vida. | O2: puntaje 2E | P2: Los ricos deben pagar relativamente más impuestos que los pobres | Q2: puntaje 3E | R2: El país sólo puede crecer a largo plazo si reorienta sus políticas hacia una economía de mercado y libre comercio | S2: puntaje 4E | T2: El gobierno siempre debe intervenir en el mercado cuando lo crea necesario | U2: puntaje 5E | V2: Aquellos que puedan trabajar, y rechacen la oportunidad, no deberían esperar ayuda social | W2: puntaje 6E | X2: El gasto público en planes y asistencia social debe reducirse a un mínimo y en su lugar debe gastarse el dinero público en planes de empleo e inversión | Y2: puntaje 7E | Z2: La única responsabilidad social de una empresa debería ser proporcionar utilidades a sus accionistas | AA2: puntaje 8E | AB2: suma eje economico | AC2: eje econ | AD2: Altos salarios para funcionarios estatales (en los 3 poderes) son beneficiosos por disminuir las posibilidades de que estos cometan actos de corrupción | AE2: puntaje 1S | AF2: Las medidas de restricción de la circulación y aislamiento obligatorio durante la pandemia fueron excesivas y un atropello a la libertad individual de los ciudadanos | AG2: puntaje 2S | AH2: El movimiento feminista carece de sentido ya que actualmente mujeres y hombres se encuentran en pie de igualdad | AI2: puntaje 3S | AJ2: El aborto, cuando no esté amenazada la vida de la madre, siempre debería ser ilegal | AK2: puntaje 4S | AL2: El cambio climático es una problemática alarmante y a la que todos los Estados deberían prestar atención | AM2: puntaje 5S | AN2: Los contribuyentes deberían financiar con impuestos aquellos teatros o museos que no fuesen rentables por sí mismos | AO2: puntaje 6S | AP2: En la justicia penal la rehabilitación debería ser más importante que el castigo | AQ2: puntaje 7S | AR2: Los extranjeros no deberían acceder a educación y salud gratuita | AS2: puntaje 8S | AT2: El Estado no debería obligar a vacunar a los niños | AU2: puntaje 9S | AV2: eje social | AW2: El peronismo es el responsable de arruinar nuestro país en los últimos años | AX2: La política tradicional es responsable de la crisis económica y social del país | AY2: El FMI es partícipe del fracaso económico de los últimos años | AZ2: La falta de dólares es uno de los principales problemas de la argentina | BA2: Se puede pagar el precio de cierto grado de corrupción, siempre que se solucionen los problemas del país | BB2: Estoy dispuesto a sacrificar derechos políticos por más seguridad | BC2: Estoy dispuesto a sacrificar derechos políticos por más bienestar económico | BD2: Si me asegura 30 años de estabilidad económica y crecimiento, estoy dispuesto a sacrificar derechos políticos | BE2: La vida en los barrios cerrados ("countries") es de mejor calidad que en barrios abiertos, incluso si estos son seguros | BF2: Suponiendo un transporte público eficiente, de calidad y bajo costo, estaría dispuesto a disminuir el uso del automóvil particular | BG2: La educación secundaria privada prepara mejor a los ciudadanos que la escuela pública | BH2: ¿Con cuáles de los siguientes términos se identifica? (Puede elegir más de uno) [De derecha] | BI2: ¿Con cuáles de los siguientes términos se identifica? (Puede elegir más de uno) [De izquierda] | BJ2: ¿Con cuáles de los siguientes términos se identifica? (Puede elegir más de uno) [De centro] | BK2: ¿Con cuáles de los siguientes términos se identifica? (Puede elegir más de uno) [Progresista] | BL2: ¿Con cuáles de los siguientes términos se identifica? (Puede elegir más de uno) [Conservador] | BM2: ¿Con cuáles de los siguientes términos se identifica? (Puede elegir más de uno) [Liberal] | BN2: ¿Con cuáles de los siguientes términos se identifica? (Puede elegir más de uno) [Socialista] | BO2: ¿Con cuáles de los siguientes términos se identifica? (Puede elegir más de uno) [Del PRO] | BP2: ¿Con cuáles de los siguientes términos se identifica? (Puede elegir más de uno) [Peronista] | BQ2: ¿Con cuáles de los siguientes términos se identifica? (Puede elegir más de uno) [Kirchnerista] | BR2: ¿Con cuáles de los siguientes términos se identifica? (Puede elegir más de uno) [Libertario] | BS2: ¿Con cuáles de los siguientes términos se identifica? (Puede elegir más de uno) [Radical] | BT2: ¿Con cuáles de los siguientes términos se identifica? (Puede elegir más de uno) [Macrista] | BU2: ¿Con cuáles de los siguientes términos se identifica? (Puede elegir más de uno) [Feminista] | BV2: ¿Con cuáles de los siguientes términos se identifica? (Puede elegir más de uno) [Ecologista] | BW2: ¿Con cuáles de los siguientes términos se identifica? (Puede elegir más de uno) [Anarquista] | BX2: ¿Cómo votó para Presidente en las elecciones PASO de agosto de 2023? | BY2: ¿Cómo votó para Presidente en las elecciones generales de octubre de 2023? | BZ2: ¿Cómo votó para Presidente en el ballotage de noviembre de 2023? | CA2: ¿Cuál es tu sexo registrado al nacer?
A3: 45547.897 | B3: 00686630540 | C3: 2002 | D3: Cuarto año | E3: Varón | F3: Universitario incompleto | G3: Universitario incompleto | H3: Clase Alta (ABC1): más de $2.850.000 mensuales | I3: Familia | J3: Otra localidad en la Provincia de Córdoba | K3: . | L3: Totalmente en Desacuerdo | M3: =IF(L3="Totalmente de Acuerdo",-1,IF(L3="Muy de Acuerdo",-0.66,IF(L3="Levemente de Acuerdo",-0.33,IF(L3="Levemente en Desacuerdo",0.33,IF(L3="Muy en Desacuerdo",0.66,IF(L3="Totalmente en Desacuerdo",1,"error")))))) -> 1 | N3: Levemente de Acuerdo | O3: =IF(N3="Totalmente de Acuerdo",1,IF(N3="Muy de Acuerdo",0.66,IF(N3="Levemente de Acuerdo",0.33,IF(N3="Levemente en Desacuerdo",-0.33,IF(N3="Muy en Desacuerdo",-0.66,IF(N3="Totalmente en Desacuerdo",-1,"error")))))) -> 0.33 | P3: Muy de Acuerdo | Q3: =IF(P3="Totalmente de Acuerdo",-1,IF(P3="Muy de Acuerdo",-0.66,IF(P3="Levemente de Acuerdo",-0.33,IF(P3="Levemente en Desacuerdo",0.33,IF(P3="Muy en Desacuerdo",0.66,IF(P3="Totalmente en Desacuerdo",1,"error")))))) -> -0.66 | R3: Totalmente de Acuerdo | S3: =IF(R3="Totalmente de Acuerdo",1,IF(R3="Muy de Acuerdo",0.66,IF(R3="Levemente de Acuerdo",0.33,IF(R3="Levemente en Desacuerdo",-0.33,IF(R3="Muy en Desacuerdo",-0.66,IF(R3="Totalmente en Desacuerdo",-1,"error")))))) -> 1 | T3: Muy en Desacuerdo | U3: =IF(T3="Totalmente de Acuerdo",-1,IF(T3="Muy de Acuerdo",-0.66,IF(T3="Levemente de Acuerdo",-0.33,IF(T3="Levemente en Desacuerdo",0.33,IF(T3="Muy en Desacuerdo",0.66,IF(T3="Totalmente en Desacuerdo",1,"error")))))) -> 0.66 | V3: Totalmente de Acuerdo | W3: =IF(V3="Totalmente de Acuerdo",1,IF(V3="Muy de Acuerdo",0.66,IF(V3="Levemente de Acuerdo",0.33,IF(V3="Levemente en Desacuerdo",-0.33,IF(V3="Muy en Desacuerdo",-0.66,IF(V3="Totalmente en Desacuerdo",-1,"error")))))) -> 1 | X3: Totalmente de Acuerdo | Y3: =IF(X3="Totalmente de Acuerdo",1,IF(X3="Muy de Acuerdo",0.66,IF(X3="Levemente de Acuerdo",0.33,IF(X3="Levemente en Desacuerdo",-0.33,IF(X3="Muy en Desacuerdo",-0.66,IF(X3="Totalmente en Desacuerdo",-1,"error")))))) -> 1 | Z3: Muy en Desacuerdo | AA3: =IF(Z3="Totalmente de Acuerdo",1,IF(Z3="Muy de Acuerdo",0.66,IF(Z3="Levemente en Acuerdo",0.33,IF(Z3="Levemente en Desacuerdo",-0.33,IF(Z3="Muy en Desacuerdo",-0.66,IF(Z3="Totalmente en Desacuerdo",-1,"error")))))) -> -0.66 | AB3: =+AA3+Y3+W3+U3+S3+Q3+O3+M3 -> 3.67 | AC3: =+AB3*AB$36 -> 4.12875 | AD3: Levemente en Desacuerdo | AE3: =IF(AD3="Totalmente de Acuerdo",1,IF(AD3="Muy de Acuerdo",0.66,IF(AD3="Levemente de Acuerdo",0.33,IF(AD3="Levemente en Desacuerdo",-0.33,IF(AD3="Muy en Desacuerdo",-0.66,IF(AD3="Totalmente en Desacuerdo",-1,"error")))))) -> -0.33 | AF3: Totalmente de Acuerdo | AG3: =IF(AF3="Totalmente de Acuerdo",-1,IF(AF3="Muy de Acuerdo",-0.66,IF(AF3="Levemente de Acuerdo",-0.33,IF(AF3="Levemente en Desacuerdo",0.33,IF(AF3="Muy en Desacuerdo",0.66,IF(AF3="Totalmente en Desacuerdo",1,"error")))))) -> -1 | AH3: Levemente en Desacuerdo | AI3: =IF(AH3="Totalmente de Acuerdo",1,IF(AH3="Muy de Acuerdo",0.66,IF(AH3="Levemente de Acuerdo",0.33,IF(AH3="Levemente en Desacuerdo",-0.33,IF(AH3="Muy en Desacuerdo",-0.66,IF(AH3="Totalmente en Desacuerdo",-1,"error")))))) -> -0.33 | AJ3: Levemente en Desacuerdo | AK3: =IF(AJ3="Totalmente de Acuerdo",1,IF(AJ3="Muy de Acuerdo",0.66,IF(AJ3="Levemente de Acuerdo",0.33,IF(AJ3="Levemente en Desacuerdo",-0.33,IF(AJ3="Muy en Desacuerdo",-0.66,IF(AJ3="Totalmente en Desacuerdo",-1,"error")))))) -> -0.33 | AL3: Muy en Desacuerdo | AM3: =IF(AL3="Totalmente de Acuerdo",-1,IF(AL3="Muy de Acuerdo",-0.66,IF(AL3="Levemente de Acuerdo",-0.33,IF(AL3="Levemente en Desacuerdo",0.33,IF(AL3="Muy en Desacuerdo",0.66,IF(AL3="Totalmente en Desacuerdo",1,"error")))))) -> 0.66 | AN3: Totalmente en Desacuerdo | AO3: =IF(AN3="Totalmente de Acuerdo",-1,IF(AN3="Muy de Acuerdo",-0.66,IF(AN3="Levemente de Acuerdo",-0.33,IF(AN3="Levemente en Desacuerdo",0.33,IF(AN3="Muy en Desacuerdo",0.66,IF(AN3="Totalmente en Desacuerdo",1,"error")))))) -> 1 | AP3: Muy en Desacuerdo | AQ3: =IF(AP3="Totalmente de Acuerdo",-1,IF(AP3="Muy de Acuerdo",-0.66,IF(AP3="Levemente de Acuerdo",-0.33,IF(AP3="Levemente en Desacuerdo",0.33,IF(AP3="Muy en Desacuerdo",0.66,IF(AP3="Totalmente en Desacuerdo",1,"error")))))) -> 0.66 | AR3: Totalmente de Acuerdo | AS3: =IF(AR3="Totalmente de Acuerdo",1,IF(AR3="Muy de Acuerdo",0.66,IF(AR3="Levemente de Acuerdo",0.33,IF(AR3="Levemente en Desacuerdo",-0.33,IF(AR3="Muy en Desacuerdo",-0.66,IF(AR3="Totalmente en Desacuerdo",-1,"error")))))) -> 1 | AT3: Totalmente en Desacuerdo | AU3: =IF(AT3="Totalmente de Acuerdo",-1,IF(AT3="Muy de Acuerdo",-0.66,IF(AT3="Levemente de Acuerdo",-0.33,IF(AT3="Levemente en Desacuerdo",0.33,IF(AT3="Muy en Desacuerdo",0.66,IF(AT3="Totalmente en Desacuerdo",1,"error")))))) -> 1 | AV3: =AU3+AS3+AQ3+AO3+AM3+AK3+AI3+AG3+AE3 -> 2.33 | AW3: Totalmente de Acuerdo | AX3: Muy en Desacuerdo | AY3: Totalmente en Desacuerdo | AZ3: Muy de Acuerdo | BA3: Totalmente en Desacuerdo | BB3: Totalmente de Acuerdo | BC3: Levemente de Acuerdo | BD3: Levemente de Acuerdo | BE3: Levemente en Desacuerdo | BF3: Muy en Desacuerdo | BG3: Muy de Acuerdo | BH3: Me identifico | BL3: Me identifico | BX3: Patricia Bullrich (Juntos por el Cambio) | BY3: Javier Milei (La Libertad Avanza) | BZ3: Javier Milei (La Libertad Avanza)
A4: 45547.898 | B4: 00164890275 | C4: 1998 | D4: Quinto año | E4: Varón | F4: Universitario completo | G4: Universitario incompleto | H4: Clase Alta (ABC1): más de $2.850.000 mensuales | I4: Familia | J4: Otra localidad en otra Provincia | K4: . | L4: Levemente de Acuerdo | M4: =IF(L4="Totalmente de Acuerdo",-1,IF(L4="Muy de Acuerdo",-0.66,IF(L4="Levemente de Acuerdo",-0.33,IF(L4="Levemente en Desacuerdo",0.33,IF(L4="Muy en Desacuerdo",0.66,IF(L4="Totalmente en Desacuerdo",1,"error")))))) -> -0.33 | N4: Muy en Desacuerdo | O4: =IF(N4="Totalmente de Acuerdo",1,IF(N4="Muy de Acuerdo",0.66,IF(N4="Levemente de Acuerdo",0.33,IF(N4="Levemente en Desacuerdo",-0.33,IF(N4="Muy en Desacuerdo",-0.66,IF(N4="Totalmente en Desacuerdo",-1,"error")))))) -> -0.66 | P4: Totalmente de Acuerdo | Q4: =IF(P4="Totalmente de Acuerdo",-1,IF(P4="Muy de Acuerdo",-0.66,IF(P4="Levemente de Acuerdo",-0.33,IF(P4="Levemente en Desacuerdo",0.33,IF(P4="Muy en Desacuerdo",0.66,IF(P4="Totalmente en Desacuerdo",1,"error")))))) -> -1 | R4: Levemente de Acuerdo | S4: =IF(R4="Totalmente de Acuerdo",1,IF(R4="Muy de Acuerdo",0.66,IF(R4="Levemente de Acuerdo",0.33,IF(R4="Levemente en Desacuerdo",-0.33,IF(R4="Muy en Desacuerdo",-0.66,IF(R4="Totalmente en Desacuerdo",-1,"error")))))) -> 0.33 | T4: Levemente en Desacuerdo | U4: =IF(T4="Totalmente de Acuerdo",-1,IF(T4="Muy de Acuerdo",-0.66,IF(T4="Levemente de Acuerdo",-0.33,IF(T4="Levemente en Desacuerdo",0.33,IF(T4="Muy en Desacuerdo",0.66,IF(T4="Totalmente en Desacuerdo",1,"error")))))) -> 0.33 | V4: Levemente en Desacuerdo | W4: =IF(V4="Totalmente de Acuerdo",1,IF(V4="Muy de Acuerdo",0.66,IF(V4="Levemente de Acuerdo",0.33,IF(V4="Levemente en Desacuerdo",-0.33,IF(V4="Muy en Desacuerdo",-0.66,IF(V4="Totalmente en Desacuerdo",-1,"error")))))) -> -0.33 | X4: Levemente en Desacuerdo | Y4: =IF(X4="Totalmente de Acuerdo",1,IF(X4="Muy de Acuerdo",0.66,IF(X4="Levemente de Acuerdo",0.33,IF(X4="Levemente en Desacuerdo",-0.33,IF(X4="Muy en Desacuerdo",-0.66,IF(X4="Totalmente en Desacuerdo",-1,"error")))))) -> -0.33 | Z4: Muy en Desacuerdo | AA4: =IF(Z4="Totalmente de Acuerdo",1,IF(Z4="Muy de Acuerdo",0.66,IF(Z4="Levemente en Acuerdo",0.33,IF(Z4="Levemente en Desacuerdo",-0.33,IF(Z4="Muy en Desacuerdo",-0.66,IF(Z4="Totalmente en Desacuerdo",-1,"error")))))) -> -0.66 | AB4: =+AA4+Y4+W4+U4+S4+Q4+O4+M4 -> -2.65 | AC4: =+AB4*AB$36 -> -2.98125 | AD4: Levemente de Acuerdo | AE4: =IF(AD4="Totalmente de Acuerdo",1,IF(AD4="Muy de Acuerdo",0.66,IF(AD4="Levemente de Acuerdo",0.33,IF(AD4="Levemente en Desacuerdo",-0.33,IF(AD4="Muy en Desacuerdo",-0.66,IF(AD4="Totalmente en Desacuerdo",-1,"error")))))) -> 0.33 | AF4: Levemente de Acuerdo | AG4: =IF(AF4="Totalmente de Acuerdo",-1,IF(AF4="Muy de Acuerdo",-0.66,IF(AF4="Levemente de Acuerdo",-0.33,IF(AF4="Levemente en Desacuerdo",0.33,IF(AF4="Muy en Desacuerdo",0.66,IF(AF4="Totalmente en Desacuerdo",1,"error")))))) -> -0.33 | AH4: Totalmente en Desacuerdo | AI4: =IF(AH4="Totalmente de Acuerdo",1,IF(AH4="Muy de Acuerdo",0.66,IF(AH4="Levemente de Acuerdo",0.33,IF(AH4="Levemente en Desacuerdo",-0.33,IF(AH4="Muy en Desacuerdo",-0.66,IF(AH4="Totalmente en Desacuerdo",-1,"error")))))) -> -1 | AJ4: Totalmente en Desacuerdo | AK4: =IF(AJ4="Totalmente de Acuerdo",1,IF(AJ4="Muy de Acuerdo",0.66,IF(AJ4="Levemente de Acuerdo",0.33,IF(AJ4="Levemente en Desacuerdo",-0.33,IF(AJ4="Muy en Desacuerdo",-0.66,IF(AJ4="Totalmente en Desacuerdo",-1,"error")))))) -> -1 | AL4: Muy de Acuerdo | AM4: =IF(AL4="Totalmente de Acuerdo",-1,IF(AL4="Muy de Acuerdo",-0.66,IF(AL4="Levemente de Acuerdo",-0.33,IF(AL4="Levemente en Desacuerdo",0.33,IF(AL4="Muy en Desacuerdo",0.66,IF(AL4="Totalmente en Desacuerdo",1,"error")))))) -> -0.66 | AN4: Muy de Acuerdo | AO4: =IF(AN4="Totalmente de Acuerdo",-1,IF(AN4="Muy de Acuerdo",-0.66,IF(AN4="Levemente de Acuerdo",-0.33,IF(AN4="Levemente en Desacuerdo",0.33,IF(AN4="Muy en Desacuerdo",0.66,IF(AN4="Totalmente en Desacuerdo",1,"error")))))) -> -0.66 | AP4: Muy de Acuerdo | AQ4: =IF(AP4="Totalmente de Acuerdo",-1,IF(AP4="Muy de Acuerdo",-0.66,IF(AP4="Levemente de Acuerdo",-0.33,IF(AP4="Levemente en Desacuerdo",0.33,IF(AP4="Muy en Desacuerdo",0.66,IF(AP4="Totalmente en Desacuerdo",1,"error")))))) -> -0.66 | AR4: Totalmente en Desacuerdo | AS4: =IF(AR4="Totalmente de Acuerdo",1,IF(AR4="Muy de Acuerdo",0.66,IF(AR4="Levemente de Acuerdo",0.33,IF(AR4="Levemente en Desacuerdo",-0.33,IF(AR4="Muy en Desacuerdo",-0.66,IF(AR4="Totalmente en Desacuerdo",-1,"error")))))) -> -1 | AT4: Totalmente en Desacuerdo | AU4: =IF(AT4="Totalmente de Acuerdo",-1,IF(AT4="Muy de Acuerdo",-0.66,IF(AT4="Levemente de Acuerdo",-0.33,IF(AT4="Levemente en Desacuerdo",0.33,IF(AT4="Muy en Desacuerdo",0.66,IF(AT4="Totalmente en Desacuerdo",1,"error")))))) -> 1 | AV4: =AU4+AS4+AQ4+AO4+AM4+AK4+AI4+AG4+AE4 -> -3.98 | AW4: Totalmente en Desacuerdo | AX4: Levemente de Acuerdo | AY4: Levemente de Acuerdo | AZ4: Levemente de Acuerdo | BA4: Levemente en Desacuerdo | BB4: Muy en Desacuerdo | BC4: Muy en Desacuerdo | BD4: Levemente en Desacuerdo | BE4: Levemente en Desacuerdo | BF4: Muy de Acuerdo | BG4: Levemente de Acuerdo | BJ4: Me identifico | BK4: Me identifico | BX4: Horacio Rodríguez Larreta (Juntos por el Cambio) | BY4: Sergio Massa (Unión por la Patria) | BZ4: Sergio Massa (Unión por la Patria)
A5: 45547.898 | B5: 00578280042 | C5: 2003 | D5: Tercer año | E5: Varón | F5: Universitario incompleto | G5: Terciario completo | H5: Clase Media Alta (C2): entre $1.350.001 mensuales y $2.850.000 mensuales | I5: Familia | J5: Otra localidad en la Provincia de Córdoba | K5: . | L5: Levemente en Desacuerdo | M5: =IF(L5="Totalmente de Acuerdo",-1,IF(L5="Muy de Acuerdo",-0.66,IF(L5="Levemente de Acuerdo",-0.33,IF(L5="Levemente en Desacuerdo",0.33,IF(L5="Muy en Desacuerdo",0.66,IF(L5="Totalmente en Desacuerdo",1,"error")))))) -> 0.33 | N5: Muy en Desacuerdo | O5: =IF(N5="Totalmente de Acuerdo",1,IF(N5="Muy de Acuerdo",0.66,IF(N5="Levemente de Acuerdo",0.33,IF(N5="Levemente en Desacuerdo",-0.33,IF(N5="Muy en Desacuerdo",-0.66,IF(N5="Totalmente en Desacuerdo",-1,"error")))))) -> -0.66 | P5: Muy de Acuerdo | Q5: =IF(P5="Totalmente de Acuerdo",-1,IF(P5="Muy de Acuerdo",-0.66,IF(P5="Levemente de Acuerdo",-0.33,IF(P5="Levemente en Desacuerdo",0.33,IF(P5="Muy en Desacuerdo",0.66,IF(P5="Totalmente en Desacuerdo",1,"error")))))) -> -0.66 | R5: Totalmente de Acuerdo | S5: =IF(R5="Totalmente de Acuerdo",1,IF(R5="Muy de Acuerdo",0.66,IF(R5="Levemente de Acuerdo",0.33,IF(R5="Levemente en Desacuerdo",-0.33,IF(R5="Muy en Desacuerdo",-0.66,IF(R5="Totalmente en Desacuerdo",-1,"error")))))) -> 1 | T5: Levemente de Acuerdo | U5: =IF(T5="Totalmente de Acuerdo",-1,IF(T5="Muy de Acuerdo",-0.66,IF(T5="Levemente de Acuerdo",-0.33,IF(T5="Levemente en Desacuerdo",0.33,IF(T5="Muy en Desacuerdo",0.66,IF(T5="Totalmente en Desacuerdo",1,"error")))))) -> -0.33 | V5: Totalmente de Acuerdo | W5: =IF(V5="Totalmente de Acuerdo",1,IF(V5="Muy de Acuerdo",0.66,IF(V5="Levemente de Acuerdo",0.33,IF(V5="Levemente en Desacuerdo",-0.33,IF(V5="Muy en Desacuerdo",-0.66,IF(V5="Totalmente en Desacuerdo",-1,"error")))))) -> 1 | X5: Muy de Acuerdo | Y5: =IF(X5="Totalmente de Acuerdo",1,IF(X5="Muy de Acuerdo",0.66,IF(X5="Levemente de Acuerdo",0.33,IF(X5="Levemente en Desacuerdo",-0.33,IF(X5="Muy en Desacuerdo",-0.66,IF(X5="Totalmente en Desacuerdo",-1,"error")))))) -> 0.66 | Z5: Muy en Desacuerdo | AA5: =IF(Z5="Totalmente de Acuerdo",1,IF(Z5="Muy de Acuerdo",0.66,IF(Z5="Levemente en Acuerdo",0.33,IF(Z5="Levemente en Desacuerdo",-0.33,IF(Z5="Muy en Desacuerdo",-0.66,IF(Z5="Totalmente en Desacuerdo",-1,"error")))))) -> -0.66 | AB5: =+AA5+Y5+W5+U5+S5+Q5+O5+M5 -> 0.68 | AC5: =+AB5*AB$36 -> 0.765 | AD5: Totalmente de Acuerdo | AE5: =IF(AD5="Totalmente de Acuerdo",1,IF(AD5="Muy de Acuerdo",0.66,IF(AD5="Levemente de Acuerdo",0.33,IF(AD5="Levemente en Desacuerdo",-0.33,IF(AD5="Muy en Desacuerdo",-0.66,IF(AD5="Totalmente en Desacuerdo",-1,"error")))))) -> 1 | AF5: Totalmente de Acuerdo | AG5: =IF(AF5="Totalmente de Acuerdo",-1,IF(AF5="Muy de Acuerdo",-0.66,IF(AF5="Levemente de Acuerdo",-0.33,IF(AF5="Levemente en Desacuerdo",0.33,IF(AF5="Muy en Desacuerdo",0.66,IF(AF5="Totalmente en Desacuerdo",1,"error")))))) -> -1 | AH5: Levemente de Acuerdo | AI5: =IF(AH5="Totalmente de Acuerdo",1,IF(AH5="Muy de Acuerdo",0.66,IF(AH5="Levemente de Acuerdo",0.33,IF(AH5="Levemente en Desacuerdo",-0.33,IF(AH5="Muy en Desacuerdo",-0.66,IF(AH5="Totalmente en Desacuerdo",-1,"error")))))) -> 0.33 | AJ5: Totalmente en Desacuerdo | AK5: =IF(AJ5="Totalmente de Acuerdo",1,IF(AJ5="Muy de Acuerdo",0.66,IF(AJ5="Levemente de Acuerdo",0.33,IF(AJ5="Levemente en Desacuerdo",-0.33,IF(AJ5="Muy en Desacuerdo",-0.66,IF(AJ5="Totalmente en Desacuerdo",-1,"error")))))) -> -1 | AL5: Levemente en Desacuerdo | AM5: =IF(AL5="Totalmente de Acuerdo",-1,IF(AL5="Muy de Acuerdo",-0.66,IF(AL5="Levemente de Acuerdo",-0.33,IF(AL5="Levemente en Desacuerdo",0.33,IF(AL5="Muy en Desacuerdo",0.66,IF(AL5="Totalmente en Desacuerdo",1,"error")))))) -> 0.33 | AN5: Totalmente en Desacuerdo | AO5: =IF(AN5="Totalmente de Acuerdo",-1,IF(AN5="Muy de Acuerdo",-0.66,IF(AN5="Levemente de Acuerdo",-0.33,IF(AN5="Levemente en Desacuerdo",0.33,IF(AN5="Muy en Desacuerdo",0.66,IF(AN5="Totalmente en Desacuerdo",1,"error")))))) -> 1 | AP5: Totalmente en Desacuerdo | AQ5: =IF(AP5="Totalmente de Acuerdo",-1,IF(AP5="Muy de Acuerdo",-0.66,IF(AP5="Levemente de Acuerdo",-0.33,IF(AP5="Levemente en Desacuerdo",0.33,IF(AP5="Muy en Desacuerdo",0.66,IF(AP5="Totalmente en Desacuerdo",1,"error")))))) -> 1 | AR5: Levemente en Desacuerdo | AS5: =IF(AR5="Totalmente de Acuerdo",1,IF(AR5="Muy de Acuerdo",0.66,IF(AR5="Levemente de Acuerdo",0.33,IF(AR5="Levemente en Desacuerdo",-0.33,IF(AR5="Muy en Desacuerdo",-0.66,IF(AR5="Totalmente en Desacuerdo",-1,"error")))))) -> -0.33 | AT5: Muy en Desacuerdo | AU5: =IF(AT5="Totalmente de Acuerdo",-1,IF(AT5="Muy de Acuerdo",-0.66,IF(AT5="Levemente de Acuerdo",-0.33,IF(AT5="Levemente en Desacuerdo",0.33,IF(AT5="Muy en Desacuerdo",0.66,IF(AT5="Totalmente en Desacuerdo",1,"error")))))) -> 0.66 | AV5: =AU5+AS5+AQ5+AO5+AM5+AK5+AI5+AG5+AE5 -> 1.99 | AW5: Levemente en Desacuerdo | AX5: Muy de Acuerdo | AY5: Totalmente en Desacuerdo | AZ5: Muy de Acuerdo | BA5: Levemente de Acuerdo | BB5: Levemente de Acuerdo | BC5: Levemente de Acuerdo | BD5: Totalmente de Acuerdo | BE5: Muy de Acuerdo | BF5: Levemente en Desacuerdo | BG5: Muy de Acuerdo | BH5: Me identifico | BL5: Me identifico | BM5: Me identifico | BX5: Javier Milei (La Libertad Avanza) | BY5: Javier Milei (La Libertad Avanza) | BZ5: Javier Milei (La Libertad Avanza)
A6: 45547.899 | B6: 00464782483 | C6: 2001 | D6: Cuarto año | E6: Varón | F6: Universitario completo | G6: Universitario completo | H6: Clase Media Alta (C2): entre $1.350.001 mensuales y $2.850.000 mensuales | I6: Familia | J6: Otra localidad en la Provincia de Córdoba | K6: . | L6: Muy de Acuerdo | M6: =IF(L6="Totalmente de Acuerdo",-1,IF(L6="Muy de Acuerdo",-0.66,IF(L6="Levemente de Acuerdo",-0.33,IF(L6="Levemente en Desacuerdo",0.33,IF(L6="Muy en Desacuerdo",0.66,IF(L6="Totalmente en Desacuerdo",1,"error")))))) -> -0.66 | N6: Levemente de Acuerdo | O6: =IF(N6="Totalmente de Acuerdo",1,IF(N6="Muy de Acuerdo",0.66,IF(N6="Levemente de Acuerdo",0.33,IF(N6="Levemente en Desacuerdo",-0.33,IF(N6="Muy en Desacuerdo",-0.66,IF(N6="Totalmente en Desacuerdo",-1,"error")))))) -> 0.33 | P6: Levemente de Acuerdo | Q6: =IF(P6="Totalmente de Acuerdo",-1,IF(P6="Muy de Acuerdo",-0.66,IF(P6="Levemente de Acuerdo",-0.33,IF(P6="Levemente en Desacuerdo",0.33,IF(P6="Muy en Desacuerdo",0.66,IF(P6="Totalmente en Desacuerdo",1,"error")))))) -> -0.33 | R6: Levemente de Acuerdo | S6: =IF(R6="Totalmente de Acuerdo",1,IF(R6="Muy de Acuerdo",0.66,IF(R6="Levemente de Acuerdo",0.33,IF(R6="Levemente en Desacuerdo",-0.33,IF(R6="Muy en Desacuerdo",-0.66,IF(R6="Totalmente en Desacuerdo",-1,"error")))))) -> 0.33 | T6: Muy de Acuerdo | U6: =IF(T6="Totalmente de Acuerdo",-1,IF(T6="Muy de Acuerdo",-0.66,IF(T6="Levemente de Acuerdo",-0.33,IF(T6="Levemente en Desacuerdo",0.33,IF(T6="Muy en Desacuerdo",0.66,IF(T6="Totalmente en Desacuerdo",1,"error")))))) -> -0.66 | V6: Muy de Acuerdo | W6: =IF(V6="Totalmente de Acuerdo",1,IF(V6="Muy de Acuerdo",0.66,IF(V6="Levemente de Acuerdo",0.33,IF(V6="Levemente en Desacuerdo",-0.33,IF(V6="Muy en Desacuerdo",-0.66,IF(V6="Totalmente en Desacuerdo",-1,"error")))))) -> 0.66 | X6: Muy de Acuerdo | Y6: =IF(X6="Totalmente de Acuerdo",1,IF(X6="Muy de Acuerdo",0.66,IF(X6="Levemente de Acuerdo",0.33,IF(X6="Levemente en Desacuerdo",-0.33,IF(X6="Muy en Desacuerdo",-0.66,IF(X6="Totalmente en Desacuerdo",-1,"error")))))) -> 0.66 | Z6: Levemente en Acuerdo | AA6: =IF(Z6="Totalmente de Acuerdo",1,IF(Z6="Muy de Acuerdo",0.66,IF(Z6="Levemente en Acuerdo",0.33,IF(Z6="Levemente en Desacuerdo",-0.33,IF(Z6="Muy en Desacuerdo",-0.66,IF(Z6="Totalmente en Desacuerdo",-1,"error")))))) -> 0.33 | AB6: =+AA6+Y6+W6+U6+S6+Q6+O6+M6 -> 0.66 | AC6: =+AB6*AB$36 -> 0.7425 | AD6: Levemente de Acuerdo | AE6: =IF(AD6="Totalmente de Acuerdo",1,IF(AD6="Muy de Acuerdo",0.66,IF(AD6="Levemente de Acuerdo",0.33,IF(AD6="Levemente en Desacuerdo",-0.33,IF(AD6="Muy en Desacuerdo",-0.66,IF(AD6="Totalmente en Desacuerdo",-1,"error")))))) -> 0.33 | AF6: Totalmente de Acuerdo | AG6: =IF(AF6="Totalmente de Acuerdo",-1,IF(AF6="Muy de Acuerdo",-0.66,IF(AF6="Levemente de Acuerdo",-0.33,IF(AF6="Levemente en Desacuerdo",0.33,IF(AF6="Muy en Desacuerdo",0.66,IF(AF6="Totalmente en Desacuerdo",1,"error")))))) -> -1 | AH6: Muy de Acuerdo | AI6: =IF(AH6="Totalmente de Acuerdo",1,IF(AH6="Muy de Acuerdo",0.66,IF(AH6="Levemente de Acuerdo",0.33,IF(AH6="Levemente en Desacuerdo",-0.33,IF(AH6="Muy en Desacuerdo",-0.66,IF(AH6="Totalmente en Desacuerdo",-1,"error")))))) -> 0.66 | AJ6: Totalmente en Desacuerdo | AK6: =IF(AJ6="Totalmente de Acuerdo",1,IF(AJ6="Muy de Acuerdo",0.66,IF(AJ6="Levemente de Acuerdo",0.33,IF(AJ6="Levemente en Desacuerdo",-0.33,IF(AJ6="Muy en Desacuerdo",-0.66,IF(AJ6="Totalmente en Desacuerdo",-1,"error")))))) -> -1 | AL6: Muy de Acuerdo | AM6: =IF(AL6="Totalmente de Acuerdo",-1,IF(AL6="Muy de Acuerdo",-0.66,IF(AL6="Levemente de Acuerdo",-0.33,IF(AL6="Levemente en Desacuerdo",0.33,IF(AL6="Muy en Desacuerdo",0.66,IF(AL6="Totalmente en Desacuerdo",1,"error")))))) -> -0.66 | AN6: Levemente en Desacuerdo | AO6: =IF(AN6="Totalmente de Acuerdo",-1,IF(AN6="Muy de Acuerdo",-0.66,IF(AN6="Levemente de Acuerdo",-0.33,IF(AN6="Levemente en Desacuerdo",0.33,IF(AN6="Muy en Desacuerdo",0.66,IF(AN6="Totalmente en Desacuerdo",1,"error")))))) -> 0.33 | AP6: Levemente en Desacuerdo | AQ6: =IF(AP6="Totalmente de Acuerdo",-1,IF(AP6="Muy de Acuerdo",-0.66,IF(AP6="Levemente de Acuerdo",-0.33,IF(AP6="Levemente en Desacuerdo",0.33,IF(AP6="Muy en Desacuerdo",0.66,IF(AP6="Totalmente en Desacuerdo",1,"error")))))) -> 0.33 | AR6: Muy de Acuerdo | AS6: =IF(AR6="Totalmente de Acuerdo",1,IF(AR6="Muy de Acuerdo",0.66,IF(AR6="Levemente de Acuerdo",0.33,IF(AR6="Levemente en Desacuerdo",-0.33,IF(AR6="Muy en Desacuerdo",-0.66,IF(AR6="Totalmente en Desacuerdo",-1,"error")))))) -> 0.66 | AT6: Levemente en Desacuerdo | AU6: =IF(AT6="Totalmente de Acuerdo",-1,IF(AT6="Muy de Acuerdo",-0.66,IF(AT6="Levemente de Acuerdo",-0.33,IF(AT6="Levemente en Desacuerdo",0.33,IF(AT6="Muy en Desacuerdo",0.66,IF(AT6="Totalmente en Desacuerdo",1,"error")))))) -> 0.33 | AV6: =AU6+AS6+AQ6+AO6+AM6+AK6+AI6+AG6+AE6 -> -0.02 | AW6: Levemente de Acuerdo | AX6: Levemente de Acuerdo | AY6: Levemente en Desacuerdo | AZ6: Levemente de Acuerdo | BA6: Levemente de Acuerdo | BB6: Levemente de Acuerdo | BC6: Levemente de Acuerdo | BD6: Levemente de Acuerdo | BE6: Muy de Acuerdo | BF6: Muy de Acuerdo | BG6: Muy de Acuerdo | BM6: Me identifico | BX6: Javier Milei (La Libertad Avanza) | BY6: Javier Milei (La Libertad Avanza) | BZ6: Javier Milei (La Libertad Avanza)
A7: 45547.899 | B7: 00661842297 | C7: 2000 | D7: Cuarto año | E7: Varón | F7: Universitario incompleto | G7: Universitario completo | H7: Clase Media Alta (C2): entre $1.350.001 mensuales y $2.850.000 mensuales | I7: Familia | J7: Otra localidad en otra Provincia | K7: . | L7: Levemente en Desacuerdo | M7: =IF(L7="Totalmente de Acuerdo",-1,IF(L7="Muy de Acuerdo",-0.66,IF(L7="Levemente de Acuerdo",-0.33,IF(L7="Levemente en Desacuerdo",0.33,IF(L7="Muy en Desacuerdo",0.66,IF(L7="Totalmente en Desacuerdo",1,"error")))))) -> 0.33 | N7: Levemente en Desacuerdo | O7: =IF(N7="Totalmente de Acuerdo",1,IF(N7="Muy de Acuerdo",0.66,IF(N7="Levemente de Acuerdo",0.33,IF(N7="Levemente en Desacuerdo",-0.33,IF(N7="Muy en Desacuerdo",-0.66,IF(N7="Totalmente en Desacuerdo",-1,"error")))))) -> -0.33 | P7: Muy de Acuerdo | Q7: =IF(P7="Totalmente de Acuerdo",-1,IF(P7="Muy de Acuerdo",-0.66,IF(P7="Levemente de Acuerdo",-0.33,IF(P7="Levemente en Desacuerdo",0.33,IF(P7="Muy en Desacuerdo",0.66,IF(P7="Totalmente en Desacuerdo",1,"error")))))) -> -0.66 | R7: Muy de Acuerdo | S7: =IF(R7="Totalmente de Acuerdo",1,IF(R7="Muy de Acuerdo",0.66,IF(R7="Levemente de Acuerdo",0.33,IF(R7="Levemente en Desacuerdo",-0.33,IF(R7="Muy en Desacuerdo",-0.66,IF(R7="Totalmente en Desacuerdo",-1,"error")))))) -> 0.66 | T7: Levemente de Acuerdo | U7: =IF(T7="Totalmente de Acuerdo",-1,IF(T7="Muy de Acuerdo",-0.66,IF(T7="Levemente de Acuerdo",-0.33,IF(T7="Levemente en Desacuerdo",0.33,IF(T7="Muy en Desacuerdo",0.66,IF(T7="Totalmente en Desacuerdo",1,"error")))))) -> -0.33 | V7: Levemente en Desacuerdo | W7: =IF(V7="Totalmente de Acuerdo",1,IF(V7="Muy de Acuerdo",0.66,IF(V7="Levemente de Acuerdo",0.33,IF(V7="Levemente en Desacuerdo",-0.33,IF(V7="Muy en Desacuerdo",-0.66,IF(V7="Totalmente en Desacuerdo",-1,"error")))))) -> -0.33 | X7: Levemente de Acuerdo | Y7: =IF(X7="Totalmente de Acuerdo",1,IF(X7="Muy de Acuerdo",0.66,IF(X7="Levemente de Acuerdo",0.33,IF(X7="Levemente en Desacuerdo",-0.33,IF(X7="Muy en Desacuerdo",-0.66,IF(X7="Totalmente en Desacuerdo",-1,"error")))))) -> 0.33 | Z7: Muy en Desacuerdo | AA7: =IF(Z7="Totalmente de Acuerdo",1,IF(Z7="Muy de Acuerdo",0.66,IF(Z7="Levemente en Acuerdo",0.33,IF(Z7="Levemente en Desacuerdo",-0.33,IF(Z7="Muy en Desacuerdo",-0.66,IF(Z7="Totalmente en Desacuerdo",-1,"error")))))) -> -0.66 | AB7: =+AA7+Y7+W7+U7+S7+Q7+O7+M7 -> -0.99 | AC7: =+AB7*AB$36 -> -1.11375 | AD7: Muy en Desacuerdo | AE7: =IF(AD7="Totalmente de Acuerdo",1,IF(AD7="Muy de Acuerdo",0.66,IF(AD7="Levemente de Acuerdo",0.33,IF(AD7="Levemente en Desacuerdo",-0.33,IF(AD7="Muy en Desacuerdo",-0.66,IF(AD7="Totalmente en Desacuerdo",-1,"error")))))) -> -0.66 | AF7: Levemente en Desacuerdo | AG7: =IF(AF7="Totalmente de Acuerdo",-1,IF(AF7="Muy de Acuerdo",-0.66,IF(AF7="Levemente de Acuerdo",-0.33,IF(AF7="Levemente en Desacuerdo",0.33,IF(AF7="Muy en Desacuerdo",0.66,IF(AF7="Totalmente en Desacuerdo",1,"error")))))) -> 0.33 | AH7: Levemente en Desacuerdo | AI7: =IF(AH7="Totalmente de Acuerdo",1,IF(AH7="Muy de Acuerdo",0.66,IF(AH7="Levemente de Acuerdo",0.33,IF(AH7="Levemente en Desacuerdo",-0.33,IF(AH7="Muy en Desacuerdo",-0.66,IF(AH7="Totalmente en Desacuerdo",-1,"error")))))) -> -0.33 | AJ7: Totalmente en Desacuerdo | AK7: =IF(AJ7="Totalmente de Acuerdo",1,IF(AJ7="Muy de Acuerdo",0.66,IF(AJ7="Levemente de Acuerdo",0.33,IF(AJ7="Levemente en Desacuerdo",-0.33,IF(AJ7="Muy en Desacuerdo",-0.66,IF(AJ7="Totalmente en Desacuerdo",-1,"error")))))) -> -1 | AL7: Muy de Acuerdo | AM7: =IF(AL7="Totalmente de Acuerdo",-1,IF(AL7="Muy de Acuerdo",-0.66,IF(AL7="Levemente de Acuerdo",-0.33,IF(AL7="Levemente en Desacuerdo",0.33,IF(AL7="Muy en Desacuerdo",0.66,IF(AL7="Totalmente en Desacuerdo",1,"error")))))) -> -0.66 | AN7: Levemente de Acuerdo | AO7: =IF(AN7="Totalmente de Acuerdo",-1,IF(AN7="Muy de Acuerdo",-0.66,IF(AN7="Levemente de Acuerdo",-0.33,IF(AN7="Levemente en Desacuerdo",0.33,IF(AN7="Muy en Desacuerdo",0.66,IF(AN7="Totalmente en Desacuerdo",1,"error")))))) -> -0.33 | AP7: Muy en Desacuerdo | AQ7: =IF(AP7="Totalmente de Acuerdo",-1,IF(AP7="Muy de Acuerdo",-0.66,IF(AP7="Levemente de Acuerdo",-0.33,IF(AP7="Levemente en Desacuerdo",0.33,IF(AP7="Muy en Desacuerdo",0.66,IF(AP7="Totalmente en Desacuerdo",1,"error")))))) -> 0.66 | AR7: Muy de Acuerdo | AS7: =IF(AR7="Totalmente de Acuerdo",1,IF(AR7="Muy de Acuerdo",0.66,IF(AR7="Levemente de Acuerdo",0.33,IF(AR7="Levemente en Desacuerdo",-0.33,IF(AR7="Muy en Desacuerdo",-0.66,IF(AR7="Totalmente en Desacuerdo",-1,"error")))))) -> 0.66 | AT7: Levemente de Acuerdo | AU7: =IF(AT7="Totalmente de Acuerdo",-1,IF(AT7="Muy de Acuerdo",-0.66,IF(AT7="Levemente de Acuerdo",-0.33,IF(AT7="Levemente en Desacuerdo",0.33,IF(AT7="Muy en Desacuerdo",0.66,IF(AT7="Totalmente en Desacuerdo",1,"error")))))) -> -0.33 | AV7: =AU7+AS7+AQ7+AO7+AM7+AK7+AI7+AG7+AE7 -> -1.66 | AW7: Levemente en Desacuerdo | AX7: Muy de Acuerdo | AY7: Muy en Desacuerdo | AZ7: Levemente de Acuerdo | BA7: Muy en Desacuerdo | BB7: Muy en Desacuerdo | BC7: Muy en Desacuerdo | BD7: Muy en Desacuerdo | BE7: Muy de Acuerdo | BF7: Levemente de Acuerdo | BG7: Levemente en Desacuerdo | BJ7: Me identifico | BX7: No vote | BY7: Sergio Massa (Unión por la Patria) | BZ7: Sergio Massa (Unión por la Patria)
